[2025-05-04 13:25:02,419] ERROR in app: Exception on /admin/unit/new/ [GET]
Traceback (most recent call last):
  File "C:\Users\admin\AppData\Local\Programs\Python\Python311\Lib\site-packages\flask\app.py", line 2529, in wsgi_app
    response = self.full_dispatch_request()
               ^^^^^^^^^^^^^^^^^^^^^^^^^^^^
  File "C:\Users\admin\AppData\Local\Programs\Python\Python311\Lib\site-packages\flask\app.py", line 1825, in full_dispatch_request
    rv = self.handle_user_exception(e)
         ^^^^^^^^^^^^^^^^^^^^^^^^^^^^^
  File "C:\Users\admin\AppData\Local\Programs\Python\Python311\Lib\site-packages\flask\app.py", line 1823, in full_dispatch_request
    rv = self.dispatch_request()
         ^^^^^^^^^^^^^^^^^^^^^^^
  File "C:\Users\admin\AppData\Local\Programs\Python\Python311\Lib\site-packages\flask\app.py", line 1799, in dispatch_request
    return self.ensure_sync(self.view_functions[rule.endpoint])(**view_args)
           ^^^^^^^^^^^^^^^^^^^^^^^^^^^^^^^^^^^^^^^^^^^^^^^^^^^^^^^^^^^^^^^^^
  File "C:\Users\admin\AppData\Local\Programs\Python\Python311\Lib\site-packages\flask_admin\base.py", line 69, in inner
    return self._run_view(f, *args, **kwargs)
           ^^^^^^^^^^^^^^^^^^^^^^^^^^^^^^^^^^
  File "C:\Users\admin\AppData\Local\Programs\Python\Python311\Lib\site-packages\flask_admin\base.py", line 369, in _run_view
    return fn(self, *args, **kwargs)
           ^^^^^^^^^^^^^^^^^^^^^^^^^
  File "C:\Users\admin\AppData\Local\Programs\Python\Python311\Lib\site-packages\flask_admin\model\base.py", line 2093, in create_view
    form = self.create_form()
           ^^^^^^^^^^^^^^^^^^
  File "C:\Users\admin\AppData\Local\Programs\Python\Python311\Lib\site-packages\flask_admin\model\base.py", line 1332, in create_form
    return self._create_form_class(get_form_data(), obj=obj)
           ^^^^^^^^^^^^^^^^^^^^^^^^^^^^^^^^^^^^^^^^^^^^^^^^^
  File "C:\Users\admin\AppData\Local\Programs\Python\Python311\Lib\site-packages\wtforms\form.py", line 209, in __call__
    return type.__call__(cls, *args, **kwargs)
           ^^^^^^^^^^^^^^^^^^^^^^^^^^^^^^^^^^^
  File "C:\Users\admin\AppData\Local\Programs\Python\Python311\Lib\site-packages\flask_admin\form\__init__.py", line 22, in __init__
    super(BaseForm, self).__init__(formdata=formdata, obj=obj, prefix=prefix, **kwargs)
  File "C:\Users\admin\AppData\Local\Programs\Python\Python311\Lib\site-packages\wtforms\form.py", line 281, in __init__
    super().__init__(self._unbound_fields, meta=meta_obj, prefix=prefix)
  File "C:\Users\admin\AppData\Local\Programs\Python\Python311\Lib\site-packages\wtforms\form.py", line 49, in __init__
    field = meta.bind_field(self, unbound_field, options)
            ^^^^^^^^^^^^^^^^^^^^^^^^^^^^^^^^^^^^^^^^^^^^^
  File "C:\Users\admin\AppData\Local\Programs\Python\Python311\Lib\site-packages\wtforms\meta.py", line 28, in bind_field
    return unbound_field.bind(form=form, **options)
           ^^^^^^^^^^^^^^^^^^^^^^^^^^^^^^^^^^^^^^^^
  File "C:\Users\admin\AppData\Local\Programs\Python\Python311\Lib\site-packages\wtforms\fields\core.py", line 387, in bind
    return self.field_class(*self.args, **kw)
           ^^^^^^^^^^^^^^^^^^^^^^^^^^^^^^^^^^
  File "C:\Users\admin\AppData\Local\Programs\Python\Python311\Lib\site-packages\wtforms\fields\core.py", line 133, in __init__
    for k, v in flags.items():
                ^^^^^^^^^^^
AttributeError: 'tuple' object has no attribute 'items'
[2025-05-04 13:25:45,881] ERROR in app: Exception on /report/statistics [GET]
Traceback (most recent call last):
  File "C:\Users\admin\AppData\Local\Programs\Python\Python311\Lib\site-packages\flask\app.py", line 2529, in wsgi_app
    response = self.full_dispatch_request()
               ^^^^^^^^^^^^^^^^^^^^^^^^^^^^
  File "C:\Users\admin\AppData\Local\Programs\Python\Python311\Lib\site-packages\flask\app.py", line 1825, in full_dispatch_request
    rv = self.handle_user_exception(e)
         ^^^^^^^^^^^^^^^^^^^^^^^^^^^^^
  File "C:\Users\admin\AppData\Local\Programs\Python\Python311\Lib\site-packages\flask\app.py", line 1823, in full_dispatch_request
    rv = self.dispatch_request()
         ^^^^^^^^^^^^^^^^^^^^^^^
  File "C:\Users\admin\AppData\Local\Programs\Python\Python311\Lib\site-packages\flask\app.py", line 1799, in dispatch_request
    return self.ensure_sync(self.view_functions[rule.endpoint])(**view_args)
           ^^^^^^^^^^^^^^^^^^^^^^^^^^^^^^^^^^^^^^^^^^^^^^^^^^^^^^^^^^^^^^^^^
  File "C:\Users\admin\AppData\Local\Programs\Python\Python311\Lib\site-packages\flask_login\utils.py", line 290, in decorated_view
    return current_app.ensure_sync(func)(*args, **kwargs)
           ^^^^^^^^^^^^^^^^^^^^^^^^^^^^^^^^^^^^^^^^^^^^^^
  File "D:\ASRP-main\asrp\blueprints\report\report_views.py", line 14, in report_statistics
    'crime': CrimeReport,
             ^^^^^^^^^^^
NameError: name 'CrimeReport' is not defined
[2025-05-04 13:25:48,149] ERROR in app: Exception on /report/my_reports [GET]
Traceback (most recent call last):
  File "C:\Users\admin\AppData\Local\Programs\Python\Python311\Lib\site-packages\flask\app.py", line 2529, in wsgi_app
    response = self.full_dispatch_request()
               ^^^^^^^^^^^^^^^^^^^^^^^^^^^^
  File "C:\Users\admin\AppData\Local\Programs\Python\Python311\Lib\site-packages\flask\app.py", line 1825, in full_dispatch_request
    rv = self.handle_user_exception(e)
         ^^^^^^^^^^^^^^^^^^^^^^^^^^^^^
  File "C:\Users\admin\AppData\Local\Programs\Python\Python311\Lib\site-packages\flask\app.py", line 1823, in full_dispatch_request
    rv = self.dispatch_request()
         ^^^^^^^^^^^^^^^^^^^^^^^
  File "C:\Users\admin\AppData\Local\Programs\Python\Python311\Lib\site-packages\flask\app.py", line 1799, in dispatch_request
    return self.ensure_sync(self.view_functions[rule.endpoint])(**view_args)
           ^^^^^^^^^^^^^^^^^^^^^^^^^^^^^^^^^^^^^^^^^^^^^^^^^^^^^^^^^^^^^^^^^
  File "D:\ASRP-main\asrp\blueprints\report\__init__.py", line 27, in my_reports
    crime_reports = CrimeReport.query.all()
                    ^^^^^^^^^^^
NameError: name 'CrimeReport' is not defined
[2025-05-04 13:38:27,600] ERROR in app: Exception on /report/statistics [GET]
Traceback (most recent call last):
  File "C:\Users\admin\AppData\Local\Programs\Python\Python311\Lib\site-packages\flask\app.py", line 2529, in wsgi_app
    response = self.full_dispatch_request()
               ^^^^^^^^^^^^^^^^^^^^^^^^^^^^
  File "C:\Users\admin\AppData\Local\Programs\Python\Python311\Lib\site-packages\flask\app.py", line 1825, in full_dispatch_request
    rv = self.handle_user_exception(e)
         ^^^^^^^^^^^^^^^^^^^^^^^^^^^^^
  File "C:\Users\admin\AppData\Local\Programs\Python\Python311\Lib\site-packages\flask\app.py", line 1823, in full_dispatch_request
    rv = self.dispatch_request()
         ^^^^^^^^^^^^^^^^^^^^^^^
  File "C:\Users\admin\AppData\Local\Programs\Python\Python311\Lib\site-packages\flask\app.py", line 1799, in dispatch_request
    return self.ensure_sync(self.view_functions[rule.endpoint])(**view_args)
           ^^^^^^^^^^^^^^^^^^^^^^^^^^^^^^^^^^^^^^^^^^^^^^^^^^^^^^^^^^^^^^^^^
  File "C:\Users\admin\AppData\Local\Programs\Python\Python311\Lib\site-packages\flask_login\utils.py", line 290, in decorated_view
    return current_app.ensure_sync(func)(*args, **kwargs)
           ^^^^^^^^^^^^^^^^^^^^^^^^^^^^^^^^^^^^^^^^^^^^^^
  File "D:\ASRP-main\asrp\blueprints\report\report_views.py", line 54, in report_statistics
    status_stats = db.session.query(model.status, func.count(model.id)).group_by(model.status).all()
                   ^^
NameError: name 'db' is not defined
[2025-05-04 13:38:30,588] ERROR in app: Exception on /report/my_reports [GET]
Traceback (most recent call last):
  File "C:\Users\admin\AppData\Local\Programs\Python\Python311\Lib\site-packages\flask\app.py", line 2529, in wsgi_app
    response = self.full_dispatch_request()
               ^^^^^^^^^^^^^^^^^^^^^^^^^^^^
  File "C:\Users\admin\AppData\Local\Programs\Python\Python311\Lib\site-packages\flask\app.py", line 1825, in full_dispatch_request
    rv = self.handle_user_exception(e)
         ^^^^^^^^^^^^^^^^^^^^^^^^^^^^^
  File "C:\Users\admin\AppData\Local\Programs\Python\Python311\Lib\site-packages\flask\app.py", line 1823, in full_dispatch_request
    rv = self.dispatch_request()
         ^^^^^^^^^^^^^^^^^^^^^^^
  File "C:\Users\admin\AppData\Local\Programs\Python\Python311\Lib\site-packages\flask\app.py", line 1799, in dispatch_request
    return self.ensure_sync(self.view_functions[rule.endpoint])(**view_args)
           ^^^^^^^^^^^^^^^^^^^^^^^^^^^^^^^^^^^^^^^^^^^^^^^^^^^^^^^^^^^^^^^^^
  File "D:\ASRP-main\asrp\blueprints\report\__init__.py", line 27, in my_reports
    crime_reports = CrimeReport.query.all()
                    ^^^^^^^^^^^
NameError: name 'CrimeReport' is not defined
[2025-05-04 13:42:52,191] ERROR in app: Exception on /report/statistics [GET]
Traceback (most recent call last):
  File "C:\Users\admin\AppData\Local\Programs\Python\Python311\Lib\site-packages\flask\app.py", line 2529, in wsgi_app
    response = self.full_dispatch_request()
               ^^^^^^^^^^^^^^^^^^^^^^^^^^^^
  File "C:\Users\admin\AppData\Local\Programs\Python\Python311\Lib\site-packages\flask\app.py", line 1825, in full_dispatch_request
    rv = self.handle_user_exception(e)
         ^^^^^^^^^^^^^^^^^^^^^^^^^^^^^
  File "C:\Users\admin\AppData\Local\Programs\Python\Python311\Lib\site-packages\flask\app.py", line 1823, in full_dispatch_request
    rv = self.dispatch_request()
         ^^^^^^^^^^^^^^^^^^^^^^^
  File "C:\Users\admin\AppData\Local\Programs\Python\Python311\Lib\site-packages\flask\app.py", line 1799, in dispatch_request
    return self.ensure_sync(self.view_functions[rule.endpoint])(**view_args)
           ^^^^^^^^^^^^^^^^^^^^^^^^^^^^^^^^^^^^^^^^^^^^^^^^^^^^^^^^^^^^^^^^^
  File "C:\Users\admin\AppData\Local\Programs\Python\Python311\Lib\site-packages\flask_login\utils.py", line 290, in decorated_view
    return current_app.ensure_sync(func)(*args, **kwargs)
           ^^^^^^^^^^^^^^^^^^^^^^^^^^^^^^^^^^^^^^^^^^^^^^
  File "D:\ASRP-main\asrp\blueprints\report\report_views.py", line 55, in report_statistics
    status_stats = db.session.query(model.status, func.count(model.id)).group_by(model.status).all()
                                    ^^^^^^^^^^^^
AttributeError: type object 'CrimeReport' has no attribute 'status'
[2025-05-04 13:42:55,159] ERROR in app: Exception on /report/my_reports [GET]
Traceback (most recent call last):
  File "C:\Users\admin\AppData\Local\Programs\Python\Python311\Lib\site-packages\flask\app.py", line 2529, in wsgi_app
    response = self.full_dispatch_request()
               ^^^^^^^^^^^^^^^^^^^^^^^^^^^^
  File "C:\Users\admin\AppData\Local\Programs\Python\Python311\Lib\site-packages\flask\app.py", line 1825, in full_dispatch_request
    rv = self.handle_user_exception(e)
         ^^^^^^^^^^^^^^^^^^^^^^^^^^^^^
  File "C:\Users\admin\AppData\Local\Programs\Python\Python311\Lib\site-packages\flask\app.py", line 1823, in full_dispatch_request
    rv = self.dispatch_request()
         ^^^^^^^^^^^^^^^^^^^^^^^
  File "C:\Users\admin\AppData\Local\Programs\Python\Python311\Lib\site-packages\flask\app.py", line 1799, in dispatch_request
    return self.ensure_sync(self.view_functions[rule.endpoint])(**view_args)
           ^^^^^^^^^^^^^^^^^^^^^^^^^^^^^^^^^^^^^^^^^^^^^^^^^^^^^^^^^^^^^^^^^
  File "D:\ASRP-main\asrp\blueprints\report\__init__.py", line 27, in my_reports
    crime_reports = CrimeReport.query.all()
                    ^^^^^^^^^^^
NameError: name 'CrimeReport' is not defined
[2025-05-04 13:58:00,085] ERROR in app: Exception on /report/group/add [POST]
Traceback (most recent call last):
  File "D:\ASRP-main\asrp\blueprints\report\group_routes.py", line 31, in add_group_report
    db.session.commit()
  File "C:\Users\admin\AppData\Local\Programs\Python\Python311\Lib\site-packages\sqlalchemy\orm\scoping.py", line 599, in commit
    return self._proxied.commit()
           ^^^^^^^^^^^^^^^^^^^^^^
  File "C:\Users\admin\AppData\Local\Programs\Python\Python311\Lib\site-packages\sqlalchemy\orm\session.py", line 2032, in commit
    trans.commit(_to_root=True)
  File "<string>", line 2, in commit
  File "C:\Users\admin\AppData\Local\Programs\Python\Python311\Lib\site-packages\sqlalchemy\orm\state_changes.py", line 139, in _go
    ret_value = fn(self, *arg, **kw)
                ^^^^^^^^^^^^^^^^^^^^
  File "C:\Users\admin\AppData\Local\Programs\Python\Python311\Lib\site-packages\sqlalchemy\orm\session.py", line 1313, in commit
    self._prepare_impl()
  File "<string>", line 2, in _prepare_impl
  File "C:\Users\admin\AppData\Local\Programs\Python\Python311\Lib\site-packages\sqlalchemy\orm\state_changes.py", line 139, in _go
    ret_value = fn(self, *arg, **kw)
                ^^^^^^^^^^^^^^^^^^^^
  File "C:\Users\admin\AppData\Local\Programs\Python\Python311\Lib\site-packages\sqlalchemy\orm\session.py", line 1288, in _prepare_impl
    self.session.flush()
  File "C:\Users\admin\AppData\Local\Programs\Python\Python311\Lib\site-packages\sqlalchemy\orm\session.py", line 4353, in flush
    self._flush(objects)
  File "C:\Users\admin\AppData\Local\Programs\Python\Python311\Lib\site-packages\sqlalchemy\orm\session.py", line 4488, in _flush
    with util.safe_reraise():
  File "C:\Users\admin\AppData\Local\Programs\Python\Python311\Lib\site-packages\sqlalchemy\util\langhelpers.py", line 146, in __exit__
    raise exc_value.with_traceback(exc_tb)
  File "C:\Users\admin\AppData\Local\Programs\Python\Python311\Lib\site-packages\sqlalchemy\orm\session.py", line 4455, in _flush
    flush_context.finalize_flush_changes()
  File "C:\Users\admin\AppData\Local\Programs\Python\Python311\Lib\site-packages\sqlalchemy\orm\unitofwork.py", line 487, in finalize_flush_changes
    self.session._register_persistent(other)
  File "C:\Users\admin\AppData\Local\Programs\Python\Python311\Lib\site-packages\sqlalchemy\orm\session.py", line 3357, in _register_persistent
    raise exc.FlushError(
sqlalchemy.orm.exc.FlushError: Instance <GroupReport at 0x22fc8bf8990> has a NULL identity key.  If this is an auto-generated value, check that the database table allows generation of new primary key values, and that the mapped Column object is configured to expect these generated values.  Ensure also that this flush() is not occurring at an inappropriate time, such as within a load() event.

During handling of the above exception, another exception occurred:

Traceback (most recent call last):
  File "C:\Users\admin\AppData\Local\Programs\Python\Python311\Lib\site-packages\flask\app.py", line 2529, in wsgi_app
    response = self.full_dispatch_request()
               ^^^^^^^^^^^^^^^^^^^^^^^^^^^^
  File "C:\Users\admin\AppData\Local\Programs\Python\Python311\Lib\site-packages\flask\app.py", line 1825, in full_dispatch_request
    rv = self.handle_user_exception(e)
         ^^^^^^^^^^^^^^^^^^^^^^^^^^^^^
  File "C:\Users\admin\AppData\Local\Programs\Python\Python311\Lib\site-packages\flask\app.py", line 1823, in full_dispatch_request
    rv = self.dispatch_request()
         ^^^^^^^^^^^^^^^^^^^^^^^
  File "C:\Users\admin\AppData\Local\Programs\Python\Python311\Lib\site-packages\flask\app.py", line 1799, in dispatch_request
    return self.ensure_sync(self.view_functions[rule.endpoint])(**view_args)
           ^^^^^^^^^^^^^^^^^^^^^^^^^^^^^^^^^^^^^^^^^^^^^^^^^^^^^^^^^^^^^^^^^
  File "C:\Users\admin\AppData\Local\Programs\Python\Python311\Lib\site-packages\flask_login\utils.py", line 290, in decorated_view
    return current_app.ensure_sync(func)(*args, **kwargs)
           ^^^^^^^^^^^^^^^^^^^^^^^^^^^^^^^^^^^^^^^^^^^^^^
  File "D:\ASRP-main\asrp\blueprints\report\group_routes.py", line 39, in add_group_report
    return redirect(url_for('group.add_group_report'))
                    ^^^^^^^^^^^^^^^^^^^^^^^^^^^^^^^^^
  File "C:\Users\admin\AppData\Local\Programs\Python\Python311\Lib\site-packages\flask\helpers.py", line 256, in url_for
    return current_app.url_for(
           ^^^^^^^^^^^^^^^^^^^^
  File "C:\Users\admin\AppData\Local\Programs\Python\Python311\Lib\site-packages\flask\app.py", line 2034, in url_for
    return self.handle_url_build_error(error, endpoint, values)
           ^^^^^^^^^^^^^^^^^^^^^^^^^^^^^^^^^^^^^^^^^^^^^^^^^^^^
  File "C:\Users\admin\AppData\Local\Programs\Python\Python311\Lib\site-packages\flask\app.py", line 2023, in url_for
    rv = url_adapter.build(  # type: ignore[union-attr]
         ^^^^^^^^^^^^^^^^^^^^^^^^^^^^^^^^^^^^^^^^^^^^^^
  File "C:\Users\admin\AppData\Local\Programs\Python\Python311\Lib\site-packages\werkzeug\routing\map.py", line 924, in build
    raise BuildError(endpoint, values, method, self)
werkzeug.routing.exceptions.BuildError: Could not build url for endpoint 'group.add_group_report'. Did you mean 'report.group.add_group_report' instead?
[2025-05-04 14:07:13,489] ERROR in app: Exception on / [GET]
Traceback (most recent call last):
  File "C:\Users\admin\AppData\Local\Programs\Python\Python311\Lib\site-packages\flask\app.py", line 2529, in wsgi_app
    response = self.full_dispatch_request()
               ^^^^^^^^^^^^^^^^^^^^^^^^^^^^
  File "C:\Users\admin\AppData\Local\Programs\Python\Python311\Lib\site-packages\flask\app.py", line 1825, in full_dispatch_request
    rv = self.handle_user_exception(e)
         ^^^^^^^^^^^^^^^^^^^^^^^^^^^^^
  File "C:\Users\admin\AppData\Local\Programs\Python\Python311\Lib\site-packages\flask\app.py", line 1823, in full_dispatch_request
    rv = self.dispatch_request()
         ^^^^^^^^^^^^^^^^^^^^^^^
  File "C:\Users\admin\AppData\Local\Programs\Python\Python311\Lib\site-packages\flask\app.py", line 1799, in dispatch_request
    return self.ensure_sync(self.view_functions[rule.endpoint])(**view_args)
           ^^^^^^^^^^^^^^^^^^^^^^^^^^^^^^^^^^^^^^^^^^^^^^^^^^^^^^^^^^^^^^^^^
  File "D:\ASRP-main\asrp\blueprints\main\routes.py", line 8, in index
    return render_template('main/index.html')
           ^^^^^^^^^^^^^^^^^^^^^^^^^^^^^^^^^^
  File "C:\Users\admin\AppData\Local\Programs\Python\Python311\Lib\site-packages\flask\templating.py", line 147, in render_template
    return _render(app, template, context)
           ^^^^^^^^^^^^^^^^^^^^^^^^^^^^^^^
  File "C:\Users\admin\AppData\Local\Programs\Python\Python311\Lib\site-packages\flask\templating.py", line 128, in _render
    app.update_template_context(context)
  File "C:\Users\admin\AppData\Local\Programs\Python\Python311\Lib\site-packages\flask\app.py", line 997, in update_template_context
    context.update(func())
                   ^^^^^^
  File "C:\Users\admin\AppData\Local\Programs\Python\Python311\Lib\site-packages\flask_login\utils.py", line 405, in _user_context_processor
    return dict(current_user=_get_user())
                             ^^^^^^^^^^^
  File "C:\Users\admin\AppData\Local\Programs\Python\Python311\Lib\site-packages\flask_login\utils.py", line 370, in _get_user
    current_app.login_manager._load_user()
  File "C:\Users\admin\AppData\Local\Programs\Python\Python311\Lib\site-packages\flask_login\login_manager.py", line 364, in _load_user
    user = self._user_callback(user_id)
           ^^^^^^^^^^^^^^^^^^^^^^^^^^^^
  File "D:\ASRP-main\asrp\__init__.py", line 57, in load_user
    return User.query.get(int(user_id))
           ^^^^^^^^^^
  File "C:\Users\admin\AppData\Local\Programs\Python\Python311\Lib\site-packages\flask_sqlalchemy\model.py", line 22, in __get__
    return cls.query_class(
           ^^^^^^^^^^^^^^^^
  File "C:\Users\admin\AppData\Local\Programs\Python\Python311\Lib\site-packages\sqlalchemy\orm\query.py", line 276, in __init__
    self._set_entities(entities)
  File "C:\Users\admin\AppData\Local\Programs\Python\Python311\Lib\site-packages\sqlalchemy\orm\query.py", line 288, in _set_entities
    self._raw_columns = [
                        ^
  File "C:\Users\admin\AppData\Local\Programs\Python\Python311\Lib\site-packages\sqlalchemy\orm\query.py", line 289, in <listcomp>
    coercions.expect(
  File "C:\Users\admin\AppData\Local\Programs\Python\Python311\Lib\site-packages\sqlalchemy\sql\coercions.py", line 388, in expect
    insp._post_inspect
  File "C:\Users\admin\AppData\Local\Programs\Python\Python311\Lib\site-packages\sqlalchemy\util\langhelpers.py", line 1257, in __get__
    obj.__dict__[self.__name__] = result = self.fget(obj)
                                           ^^^^^^^^^^^^^^
  File "C:\Users\admin\AppData\Local\Programs\Python\Python311\Lib\site-packages\sqlalchemy\orm\mapper.py", line 2724, in _post_inspect
    self._check_configure()
  File "C:\Users\admin\AppData\Local\Programs\Python\Python311\Lib\site-packages\sqlalchemy\orm\mapper.py", line 2401, in _check_configure
    _configure_registries({self.registry}, cascade=True)
  File "C:\Users\admin\AppData\Local\Programs\Python\Python311\Lib\site-packages\sqlalchemy\orm\mapper.py", line 4214, in _configure_registries
    _do_configure_registries(registries, cascade)
  File "C:\Users\admin\AppData\Local\Programs\Python\Python311\Lib\site-packages\sqlalchemy\orm\mapper.py", line 4255, in _do_configure_registries
    mapper._post_configure_properties()
  File "C:\Users\admin\AppData\Local\Programs\Python\Python311\Lib\site-packages\sqlalchemy\orm\mapper.py", line 2418, in _post_configure_properties
    prop.init()
  File "C:\Users\admin\AppData\Local\Programs\Python\Python311\Lib\site-packages\sqlalchemy\orm\interfaces.py", line 589, in init
    self.do_init()
  File "C:\Users\admin\AppData\Local\Programs\Python\Python311\Lib\site-packages\sqlalchemy\orm\relationships.py", line 1661, in do_init
    self._generate_backref()
  File "C:\Users\admin\AppData\Local\Programs\Python\Python311\Lib\site-packages\sqlalchemy\orm\relationships.py", line 2089, in _generate_backref
    raise sa_exc.ArgumentError(
sqlalchemy.exc.ArgumentError: Error creating backref 'user' on relationship 'User.reports': property of that name exists on mapper 'Mapper[Report(bao_cao)]'
[2025-05-04 14:10:28,622] ERROR in app: Exception on /auth/login [POST]
Traceback (most recent call last):
  File "C:\Users\admin\AppData\Local\Programs\Python\Python311\Lib\site-packages\flask\app.py", line 2529, in wsgi_app
    response = self.full_dispatch_request()
               ^^^^^^^^^^^^^^^^^^^^^^^^^^^^
  File "C:\Users\admin\AppData\Local\Programs\Python\Python311\Lib\site-packages\flask\app.py", line 1825, in full_dispatch_request
    rv = self.handle_user_exception(e)
         ^^^^^^^^^^^^^^^^^^^^^^^^^^^^^
  File "C:\Users\admin\AppData\Local\Programs\Python\Python311\Lib\site-packages\flask\app.py", line 1823, in full_dispatch_request
    rv = self.dispatch_request()
         ^^^^^^^^^^^^^^^^^^^^^^^
  File "C:\Users\admin\AppData\Local\Programs\Python\Python311\Lib\site-packages\flask\app.py", line 1799, in dispatch_request
    return self.ensure_sync(self.view_functions[rule.endpoint])(**view_args)
           ^^^^^^^^^^^^^^^^^^^^^^^^^^^^^^^^^^^^^^^^^^^^^^^^^^^^^^^^^^^^^^^^^
  File "D:\ASRP-main\asrp\blueprints\auth\routes.py", line 29, in dang_nhap
    user = User.query.filter_by(email=form.email.data).first()
           ^^^^^^^^^^
  File "C:\Users\admin\AppData\Local\Programs\Python\Python311\Lib\site-packages\flask_sqlalchemy\model.py", line 22, in __get__
    return cls.query_class(
           ^^^^^^^^^^^^^^^^
  File "C:\Users\admin\AppData\Local\Programs\Python\Python311\Lib\site-packages\sqlalchemy\orm\query.py", line 276, in __init__
    self._set_entities(entities)
  File "C:\Users\admin\AppData\Local\Programs\Python\Python311\Lib\site-packages\sqlalchemy\orm\query.py", line 288, in _set_entities
    self._raw_columns = [
                        ^
  File "C:\Users\admin\AppData\Local\Programs\Python\Python311\Lib\site-packages\sqlalchemy\orm\query.py", line 289, in <listcomp>
    coercions.expect(
  File "C:\Users\admin\AppData\Local\Programs\Python\Python311\Lib\site-packages\sqlalchemy\sql\coercions.py", line 388, in expect
    insp._post_inspect
  File "C:\Users\admin\AppData\Local\Programs\Python\Python311\Lib\site-packages\sqlalchemy\util\langhelpers.py", line 1257, in __get__
    obj.__dict__[self.__name__] = result = self.fget(obj)
                                           ^^^^^^^^^^^^^^
  File "C:\Users\admin\AppData\Local\Programs\Python\Python311\Lib\site-packages\sqlalchemy\orm\mapper.py", line 2724, in _post_inspect
    self._check_configure()
  File "C:\Users\admin\AppData\Local\Programs\Python\Python311\Lib\site-packages\sqlalchemy\orm\mapper.py", line 2401, in _check_configure
    _configure_registries({self.registry}, cascade=True)
  File "C:\Users\admin\AppData\Local\Programs\Python\Python311\Lib\site-packages\sqlalchemy\orm\mapper.py", line 4214, in _configure_registries
    _do_configure_registries(registries, cascade)
  File "C:\Users\admin\AppData\Local\Programs\Python\Python311\Lib\site-packages\sqlalchemy\orm\mapper.py", line 4255, in _do_configure_registries
    mapper._post_configure_properties()
  File "C:\Users\admin\AppData\Local\Programs\Python\Python311\Lib\site-packages\sqlalchemy\orm\mapper.py", line 2418, in _post_configure_properties
    prop.init()
  File "C:\Users\admin\AppData\Local\Programs\Python\Python311\Lib\site-packages\sqlalchemy\orm\interfaces.py", line 589, in init
    self.do_init()
  File "C:\Users\admin\AppData\Local\Programs\Python\Python311\Lib\site-packages\sqlalchemy\orm\relationships.py", line 1661, in do_init
    self._generate_backref()
  File "C:\Users\admin\AppData\Local\Programs\Python\Python311\Lib\site-packages\sqlalchemy\orm\relationships.py", line 2089, in _generate_backref
    raise sa_exc.ArgumentError(
sqlalchemy.exc.ArgumentError: Error creating backref 'user' on relationship 'User.reports': property of that name exists on mapper 'Mapper[Report(bao_cao)]'
[2025-05-04 14:20:10,648] ERROR in app: Exception on /auth/login [POST]
Traceback (most recent call last):
  File "C:\Users\admin\AppData\Local\Programs\Python\Python311\Lib\site-packages\sqlalchemy\orm\mapper.py", line 2522, in get_property
    return self._props[key]
           ~~~~~~~~~~~^^^^^
KeyError: 'reports'

The above exception was the direct cause of the following exception:

Traceback (most recent call last):
  File "C:\Users\admin\AppData\Local\Programs\Python\Python311\Lib\site-packages\flask\app.py", line 2529, in wsgi_app
    response = self.full_dispatch_request()
               ^^^^^^^^^^^^^^^^^^^^^^^^^^^^
  File "C:\Users\admin\AppData\Local\Programs\Python\Python311\Lib\site-packages\flask\app.py", line 1825, in full_dispatch_request
    rv = self.handle_user_exception(e)
         ^^^^^^^^^^^^^^^^^^^^^^^^^^^^^
  File "C:\Users\admin\AppData\Local\Programs\Python\Python311\Lib\site-packages\flask\app.py", line 1823, in full_dispatch_request
    rv = self.dispatch_request()
         ^^^^^^^^^^^^^^^^^^^^^^^
  File "C:\Users\admin\AppData\Local\Programs\Python\Python311\Lib\site-packages\flask\app.py", line 1799, in dispatch_request
    return self.ensure_sync(self.view_functions[rule.endpoint])(**view_args)
           ^^^^^^^^^^^^^^^^^^^^^^^^^^^^^^^^^^^^^^^^^^^^^^^^^^^^^^^^^^^^^^^^^
  File "D:\ASRP-main\asrp\blueprints\auth\routes.py", line 29, in dang_nhap
    user = User.query.filter_by(email=form.email.data).first()
           ^^^^^^^^^^
  File "C:\Users\admin\AppData\Local\Programs\Python\Python311\Lib\site-packages\flask_sqlalchemy\model.py", line 22, in __get__
    return cls.query_class(
           ^^^^^^^^^^^^^^^^
  File "C:\Users\admin\AppData\Local\Programs\Python\Python311\Lib\site-packages\sqlalchemy\orm\query.py", line 276, in __init__
    self._set_entities(entities)
  File "C:\Users\admin\AppData\Local\Programs\Python\Python311\Lib\site-packages\sqlalchemy\orm\query.py", line 288, in _set_entities
    self._raw_columns = [
                        ^
  File "C:\Users\admin\AppData\Local\Programs\Python\Python311\Lib\site-packages\sqlalchemy\orm\query.py", line 289, in <listcomp>
    coercions.expect(
  File "C:\Users\admin\AppData\Local\Programs\Python\Python311\Lib\site-packages\sqlalchemy\sql\coercions.py", line 388, in expect
    insp._post_inspect
  File "C:\Users\admin\AppData\Local\Programs\Python\Python311\Lib\site-packages\sqlalchemy\util\langhelpers.py", line 1257, in __get__
    obj.__dict__[self.__name__] = result = self.fget(obj)
                                           ^^^^^^^^^^^^^^
  File "C:\Users\admin\AppData\Local\Programs\Python\Python311\Lib\site-packages\sqlalchemy\orm\mapper.py", line 2724, in _post_inspect
    self._check_configure()
  File "C:\Users\admin\AppData\Local\Programs\Python\Python311\Lib\site-packages\sqlalchemy\orm\mapper.py", line 2401, in _check_configure
    _configure_registries({self.registry}, cascade=True)
  File "C:\Users\admin\AppData\Local\Programs\Python\Python311\Lib\site-packages\sqlalchemy\orm\mapper.py", line 4214, in _configure_registries
    _do_configure_registries(registries, cascade)
  File "C:\Users\admin\AppData\Local\Programs\Python\Python311\Lib\site-packages\sqlalchemy\orm\mapper.py", line 4255, in _do_configure_registries
    mapper._post_configure_properties()
  File "C:\Users\admin\AppData\Local\Programs\Python\Python311\Lib\site-packages\sqlalchemy\orm\mapper.py", line 2418, in _post_configure_properties
    prop.init()
  File "C:\Users\admin\AppData\Local\Programs\Python\Python311\Lib\site-packages\sqlalchemy\orm\interfaces.py", line 589, in init
    self.do_init()
  File "C:\Users\admin\AppData\Local\Programs\Python\Python311\Lib\site-packages\sqlalchemy\orm\relationships.py", line 1661, in do_init
    self._generate_backref()
  File "C:\Users\admin\AppData\Local\Programs\Python\Python311\Lib\site-packages\sqlalchemy\orm\relationships.py", line 2147, in _generate_backref
    self._add_reverse_property(self.back_populates)
  File "C:\Users\admin\AppData\Local\Programs\Python\Python311\Lib\site-packages\sqlalchemy\orm\relationships.py", line 1592, in _add_reverse_property
    other = self.mapper.get_property(key, _configure_mappers=False)
            ^^^^^^^^^^^^^^^^^^^^^^^^^^^^^^^^^^^^^^^^^^^^^^^^^^^^^^^
  File "C:\Users\admin\AppData\Local\Programs\Python\Python311\Lib\site-packages\sqlalchemy\orm\mapper.py", line 2524, in get_property
    raise sa_exc.InvalidRequestError(
sqlalchemy.exc.InvalidRequestError: Mapper 'Mapper[Region(khu_vuc)]' has no property 'reports'.  If this property was indicated from other mappers or configure events, ensure registry.configure() has been called.
[2025-05-04 14:24:56,239] ERROR in app: Exception on /auth/login [POST]
Traceback (most recent call last):
  File "C:\Users\admin\AppData\Local\Programs\Python\Python311\Lib\site-packages\flask\app.py", line 2529, in wsgi_app
    response = self.full_dispatch_request()
               ^^^^^^^^^^^^^^^^^^^^^^^^^^^^
  File "C:\Users\admin\AppData\Local\Programs\Python\Python311\Lib\site-packages\flask\app.py", line 1825, in full_dispatch_request
    rv = self.handle_user_exception(e)
         ^^^^^^^^^^^^^^^^^^^^^^^^^^^^^
  File "C:\Users\admin\AppData\Local\Programs\Python\Python311\Lib\site-packages\flask\app.py", line 1823, in full_dispatch_request
    rv = self.dispatch_request()
         ^^^^^^^^^^^^^^^^^^^^^^^
  File "C:\Users\admin\AppData\Local\Programs\Python\Python311\Lib\site-packages\flask\app.py", line 1799, in dispatch_request
    return self.ensure_sync(self.view_functions[rule.endpoint])(**view_args)
           ^^^^^^^^^^^^^^^^^^^^^^^^^^^^^^^^^^^^^^^^^^^^^^^^^^^^^^^^^^^^^^^^^
  File "D:\ASRP-main\asrp\blueprints\auth\routes.py", line 29, in dang_nhap
    user = User.query.filter_by(email=form.email.data).first()
           ^^^^^^^^^^
  File "C:\Users\admin\AppData\Local\Programs\Python\Python311\Lib\site-packages\flask_sqlalchemy\model.py", line 22, in __get__
    return cls.query_class(
           ^^^^^^^^^^^^^^^^
  File "C:\Users\admin\AppData\Local\Programs\Python\Python311\Lib\site-packages\sqlalchemy\orm\query.py", line 276, in __init__
    self._set_entities(entities)
  File "C:\Users\admin\AppData\Local\Programs\Python\Python311\Lib\site-packages\sqlalchemy\orm\query.py", line 288, in _set_entities
    self._raw_columns = [
                        ^
  File "C:\Users\admin\AppData\Local\Programs\Python\Python311\Lib\site-packages\sqlalchemy\orm\query.py", line 289, in <listcomp>
    coercions.expect(
  File "C:\Users\admin\AppData\Local\Programs\Python\Python311\Lib\site-packages\sqlalchemy\sql\coercions.py", line 388, in expect
    insp._post_inspect
  File "C:\Users\admin\AppData\Local\Programs\Python\Python311\Lib\site-packages\sqlalchemy\util\langhelpers.py", line 1257, in __get__
    obj.__dict__[self.__name__] = result = self.fget(obj)
                                           ^^^^^^^^^^^^^^
  File "C:\Users\admin\AppData\Local\Programs\Python\Python311\Lib\site-packages\sqlalchemy\orm\mapper.py", line 2724, in _post_inspect
    self._check_configure()
  File "C:\Users\admin\AppData\Local\Programs\Python\Python311\Lib\site-packages\sqlalchemy\orm\mapper.py", line 2401, in _check_configure
    _configure_registries({self.registry}, cascade=True)
  File "C:\Users\admin\AppData\Local\Programs\Python\Python311\Lib\site-packages\sqlalchemy\orm\mapper.py", line 4214, in _configure_registries
    _do_configure_registries(registries, cascade)
  File "C:\Users\admin\AppData\Local\Programs\Python\Python311\Lib\site-packages\sqlalchemy\orm\mapper.py", line 4255, in _do_configure_registries
    mapper._post_configure_properties()
  File "C:\Users\admin\AppData\Local\Programs\Python\Python311\Lib\site-packages\sqlalchemy\orm\mapper.py", line 2418, in _post_configure_properties
    prop.init()
  File "C:\Users\admin\AppData\Local\Programs\Python\Python311\Lib\site-packages\sqlalchemy\orm\interfaces.py", line 589, in init
    self.do_init()
  File "C:\Users\admin\AppData\Local\Programs\Python\Python311\Lib\site-packages\sqlalchemy\orm\relationships.py", line 1661, in do_init
    self._generate_backref()
  File "C:\Users\admin\AppData\Local\Programs\Python\Python311\Lib\site-packages\sqlalchemy\orm\relationships.py", line 2089, in _generate_backref
    raise sa_exc.ArgumentError(
sqlalchemy.exc.ArgumentError: Error creating backref 'unit' on relationship 'Unit.extraction_requests': property of that name exists on mapper 'Mapper[ExtractionRequest(yeu_cau_trich_xuat)]'
[2025-05-04 14:29:56,860] ERROR in app: Exception on /auth/login [POST]
Traceback (most recent call last):
  File "C:\Users\admin\AppData\Local\Programs\Python\Python311\Lib\site-packages\flask\app.py", line 2529, in wsgi_app
    response = self.full_dispatch_request()
               ^^^^^^^^^^^^^^^^^^^^^^^^^^^^
  File "C:\Users\admin\AppData\Local\Programs\Python\Python311\Lib\site-packages\flask\app.py", line 1825, in full_dispatch_request
    rv = self.handle_user_exception(e)
         ^^^^^^^^^^^^^^^^^^^^^^^^^^^^^
  File "C:\Users\admin\AppData\Local\Programs\Python\Python311\Lib\site-packages\flask\app.py", line 1823, in full_dispatch_request
    rv = self.dispatch_request()
         ^^^^^^^^^^^^^^^^^^^^^^^
  File "C:\Users\admin\AppData\Local\Programs\Python\Python311\Lib\site-packages\flask\app.py", line 1799, in dispatch_request
    return self.ensure_sync(self.view_functions[rule.endpoint])(**view_args)
           ^^^^^^^^^^^^^^^^^^^^^^^^^^^^^^^^^^^^^^^^^^^^^^^^^^^^^^^^^^^^^^^^^
  File "D:\ASRP-main\asrp\blueprints\auth\routes.py", line 29, in dang_nhap
    user = User.query.filter_by(email=form.email.data).first()
           ^^^^^^^^^^
  File "C:\Users\admin\AppData\Local\Programs\Python\Python311\Lib\site-packages\flask_sqlalchemy\model.py", line 22, in __get__
    return cls.query_class(
           ^^^^^^^^^^^^^^^^
  File "C:\Users\admin\AppData\Local\Programs\Python\Python311\Lib\site-packages\sqlalchemy\orm\query.py", line 276, in __init__
    self._set_entities(entities)
  File "C:\Users\admin\AppData\Local\Programs\Python\Python311\Lib\site-packages\sqlalchemy\orm\query.py", line 288, in _set_entities
    self._raw_columns = [
                        ^
  File "C:\Users\admin\AppData\Local\Programs\Python\Python311\Lib\site-packages\sqlalchemy\orm\query.py", line 289, in <listcomp>
    coercions.expect(
  File "C:\Users\admin\AppData\Local\Programs\Python\Python311\Lib\site-packages\sqlalchemy\sql\coercions.py", line 388, in expect
    insp._post_inspect
  File "C:\Users\admin\AppData\Local\Programs\Python\Python311\Lib\site-packages\sqlalchemy\util\langhelpers.py", line 1257, in __get__
    obj.__dict__[self.__name__] = result = self.fget(obj)
                                           ^^^^^^^^^^^^^^
  File "C:\Users\admin\AppData\Local\Programs\Python\Python311\Lib\site-packages\sqlalchemy\orm\mapper.py", line 2724, in _post_inspect
    self._check_configure()
  File "C:\Users\admin\AppData\Local\Programs\Python\Python311\Lib\site-packages\sqlalchemy\orm\mapper.py", line 2401, in _check_configure
    _configure_registries({self.registry}, cascade=True)
  File "C:\Users\admin\AppData\Local\Programs\Python\Python311\Lib\site-packages\sqlalchemy\orm\mapper.py", line 4214, in _configure_registries
    _do_configure_registries(registries, cascade)
  File "C:\Users\admin\AppData\Local\Programs\Python\Python311\Lib\site-packages\sqlalchemy\orm\mapper.py", line 4255, in _do_configure_registries
    mapper._post_configure_properties()
  File "C:\Users\admin\AppData\Local\Programs\Python\Python311\Lib\site-packages\sqlalchemy\orm\mapper.py", line 2418, in _post_configure_properties
    prop.init()
  File "C:\Users\admin\AppData\Local\Programs\Python\Python311\Lib\site-packages\sqlalchemy\orm\interfaces.py", line 589, in init
    self.do_init()
  File "C:\Users\admin\AppData\Local\Programs\Python\Python311\Lib\site-packages\sqlalchemy\orm\relationships.py", line 1661, in do_init
    self._generate_backref()
  File "C:\Users\admin\AppData\Local\Programs\Python\Python311\Lib\site-packages\sqlalchemy\orm\relationships.py", line 2089, in _generate_backref
    raise sa_exc.ArgumentError(
sqlalchemy.exc.ArgumentError: Error creating backref 'region' on relationship 'Region.reports': property of that name exists on mapper 'Mapper[Report(bao_cao)]'
[2025-05-04 14:41:14,501] ERROR in app: Exception on /auth/login [POST]
Traceback (most recent call last):
  File "C:\Users\admin\AppData\Local\Programs\Python\Python311\Lib\site-packages\flask\app.py", line 2529, in wsgi_app
    response = self.full_dispatch_request()
               ^^^^^^^^^^^^^^^^^^^^^^^^^^^^
  File "C:\Users\admin\AppData\Local\Programs\Python\Python311\Lib\site-packages\flask\app.py", line 1825, in full_dispatch_request
    rv = self.handle_user_exception(e)
         ^^^^^^^^^^^^^^^^^^^^^^^^^^^^^
  File "C:\Users\admin\AppData\Local\Programs\Python\Python311\Lib\site-packages\flask\app.py", line 1823, in full_dispatch_request
    rv = self.dispatch_request()
         ^^^^^^^^^^^^^^^^^^^^^^^
  File "C:\Users\admin\AppData\Local\Programs\Python\Python311\Lib\site-packages\flask\app.py", line 1799, in dispatch_request
    return self.ensure_sync(self.view_functions[rule.endpoint])(**view_args)
           ^^^^^^^^^^^^^^^^^^^^^^^^^^^^^^^^^^^^^^^^^^^^^^^^^^^^^^^^^^^^^^^^^
  File "D:\ASRP-main\asrp\blueprints\auth\routes.py", line 29, in dang_nhap
    user = User.query.filter_by(email=form.email.data).first()
           ^^^^^^^^^^
  File "C:\Users\admin\AppData\Local\Programs\Python\Python311\Lib\site-packages\flask_sqlalchemy\model.py", line 22, in __get__
    return cls.query_class(
           ^^^^^^^^^^^^^^^^
  File "C:\Users\admin\AppData\Local\Programs\Python\Python311\Lib\site-packages\sqlalchemy\orm\query.py", line 276, in __init__
    self._set_entities(entities)
  File "C:\Users\admin\AppData\Local\Programs\Python\Python311\Lib\site-packages\sqlalchemy\orm\query.py", line 288, in _set_entities
    self._raw_columns = [
                        ^
  File "C:\Users\admin\AppData\Local\Programs\Python\Python311\Lib\site-packages\sqlalchemy\orm\query.py", line 289, in <listcomp>
    coercions.expect(
  File "C:\Users\admin\AppData\Local\Programs\Python\Python311\Lib\site-packages\sqlalchemy\sql\coercions.py", line 388, in expect
    insp._post_inspect
  File "C:\Users\admin\AppData\Local\Programs\Python\Python311\Lib\site-packages\sqlalchemy\util\langhelpers.py", line 1257, in __get__
    obj.__dict__[self.__name__] = result = self.fget(obj)
                                           ^^^^^^^^^^^^^^
  File "C:\Users\admin\AppData\Local\Programs\Python\Python311\Lib\site-packages\sqlalchemy\orm\mapper.py", line 2724, in _post_inspect
    self._check_configure()
  File "C:\Users\admin\AppData\Local\Programs\Python\Python311\Lib\site-packages\sqlalchemy\orm\mapper.py", line 2401, in _check_configure
    _configure_registries({self.registry}, cascade=True)
  File "C:\Users\admin\AppData\Local\Programs\Python\Python311\Lib\site-packages\sqlalchemy\orm\mapper.py", line 4214, in _configure_registries
    _do_configure_registries(registries, cascade)
  File "C:\Users\admin\AppData\Local\Programs\Python\Python311\Lib\site-packages\sqlalchemy\orm\mapper.py", line 4255, in _do_configure_registries
    mapper._post_configure_properties()
  File "C:\Users\admin\AppData\Local\Programs\Python\Python311\Lib\site-packages\sqlalchemy\orm\mapper.py", line 2418, in _post_configure_properties
    prop.init()
  File "C:\Users\admin\AppData\Local\Programs\Python\Python311\Lib\site-packages\sqlalchemy\orm\interfaces.py", line 589, in init
    self.do_init()
  File "C:\Users\admin\AppData\Local\Programs\Python\Python311\Lib\site-packages\sqlalchemy\orm\relationships.py", line 1661, in do_init
    self._generate_backref()
  File "C:\Users\admin\AppData\Local\Programs\Python\Python311\Lib\site-packages\sqlalchemy\orm\relationships.py", line 2089, in _generate_backref
    raise sa_exc.ArgumentError(
sqlalchemy.exc.ArgumentError: Error creating backref 'category' on relationship 'Category.reports': property of that name exists on mapper 'Mapper[Report(bao_cao)]'
[2025-05-04 14:47:12,147] ERROR in app: Exception on /report/statistics [GET]
Traceback (most recent call last):
  File "C:\Users\admin\AppData\Local\Programs\Python\Python311\Lib\site-packages\flask\app.py", line 2529, in wsgi_app
    response = self.full_dispatch_request()
               ^^^^^^^^^^^^^^^^^^^^^^^^^^^^
  File "C:\Users\admin\AppData\Local\Programs\Python\Python311\Lib\site-packages\flask\app.py", line 1825, in full_dispatch_request
    rv = self.handle_user_exception(e)
         ^^^^^^^^^^^^^^^^^^^^^^^^^^^^^
  File "C:\Users\admin\AppData\Local\Programs\Python\Python311\Lib\site-packages\flask\app.py", line 1823, in full_dispatch_request
    rv = self.dispatch_request()
         ^^^^^^^^^^^^^^^^^^^^^^^
  File "C:\Users\admin\AppData\Local\Programs\Python\Python311\Lib\site-packages\flask\app.py", line 1799, in dispatch_request
    return self.ensure_sync(self.view_functions[rule.endpoint])(**view_args)
           ^^^^^^^^^^^^^^^^^^^^^^^^^^^^^^^^^^^^^^^^^^^^^^^^^^^^^^^^^^^^^^^^^
  File "C:\Users\admin\AppData\Local\Programs\Python\Python311\Lib\site-packages\flask_login\utils.py", line 290, in decorated_view
    return current_app.ensure_sync(func)(*args, **kwargs)
           ^^^^^^^^^^^^^^^^^^^^^^^^^^^^^^^^^^^^^^^^^^^^^^
  File "D:\ASRP-main\asrp\blueprints\report\report_views.py", line 55, in report_statistics
    status_stats = db.session.query(model.status, func.count(model.id)).group_by(model.status).all()
                                    ^^^^^^^^^^^^
AttributeError: type object 'CrimeReport' has no attribute 'status'
[2025-05-04 14:59:27,006] ERROR in app: Exception on /report/crime/add [GET]
Traceback (most recent call last):
  File "C:\Users\admin\AppData\Local\Programs\Python\Python311\Lib\site-packages\flask\app.py", line 2529, in wsgi_app
    response = self.full_dispatch_request()
               ^^^^^^^^^^^^^^^^^^^^^^^^^^^^
  File "C:\Users\admin\AppData\Local\Programs\Python\Python311\Lib\site-packages\flask\app.py", line 1825, in full_dispatch_request
    rv = self.handle_user_exception(e)
         ^^^^^^^^^^^^^^^^^^^^^^^^^^^^^
  File "C:\Users\admin\AppData\Local\Programs\Python\Python311\Lib\site-packages\flask\app.py", line 1823, in full_dispatch_request
    rv = self.dispatch_request()
         ^^^^^^^^^^^^^^^^^^^^^^^
  File "C:\Users\admin\AppData\Local\Programs\Python\Python311\Lib\site-packages\flask\app.py", line 1799, in dispatch_request
    return self.ensure_sync(self.view_functions[rule.endpoint])(**view_args)
           ^^^^^^^^^^^^^^^^^^^^^^^^^^^^^^^^^^^^^^^^^^^^^^^^^^^^^^^^^^^^^^^^^
  File "C:\Users\admin\AppData\Local\Programs\Python\Python311\Lib\site-packages\flask_login\utils.py", line 290, in decorated_view
    return current_app.ensure_sync(func)(*args, **kwargs)
           ^^^^^^^^^^^^^^^^^^^^^^^^^^^^^^^^^^^^^^^^^^^^^^
  File "D:\ASRP-main\asrp\blueprints\report\crime_routes.py", line 34, in add_crime_report
    form = CrimeReportForm()
           ^^^^^^^^^^^^^^^^^
  File "C:\Users\admin\AppData\Local\Programs\Python\Python311\Lib\site-packages\wtforms\form.py", line 209, in __call__
    return type.__call__(cls, *args, **kwargs)
           ^^^^^^^^^^^^^^^^^^^^^^^^^^^^^^^^^^^
  File "D:\ASRP-main\asrp\blueprints\report\CrimeReportForm.py", line 24, in __init__
    self.status_id.choices = [(s.id, s.name) for s in Status.query.all()]
    ^^^^^^^^^^^^^^
AttributeError: 'CrimeReportForm' object has no attribute 'status_id'
[2025-05-04 15:07:02,697] ERROR in app: Exception on /report/crime/add [GET]
Traceback (most recent call last):
  File "C:\Users\admin\AppData\Local\Programs\Python\Python311\Lib\site-packages\flask\app.py", line 2529, in wsgi_app
    response = self.full_dispatch_request()
               ^^^^^^^^^^^^^^^^^^^^^^^^^^^^
  File "C:\Users\admin\AppData\Local\Programs\Python\Python311\Lib\site-packages\flask\app.py", line 1825, in full_dispatch_request
    rv = self.handle_user_exception(e)
         ^^^^^^^^^^^^^^^^^^^^^^^^^^^^^
  File "C:\Users\admin\AppData\Local\Programs\Python\Python311\Lib\site-packages\flask\app.py", line 1823, in full_dispatch_request
    rv = self.dispatch_request()
         ^^^^^^^^^^^^^^^^^^^^^^^
  File "C:\Users\admin\AppData\Local\Programs\Python\Python311\Lib\site-packages\flask\app.py", line 1799, in dispatch_request
    return self.ensure_sync(self.view_functions[rule.endpoint])(**view_args)
           ^^^^^^^^^^^^^^^^^^^^^^^^^^^^^^^^^^^^^^^^^^^^^^^^^^^^^^^^^^^^^^^^^
  File "C:\Users\admin\AppData\Local\Programs\Python\Python311\Lib\site-packages\flask_login\utils.py", line 290, in decorated_view
    return current_app.ensure_sync(func)(*args, **kwargs)
           ^^^^^^^^^^^^^^^^^^^^^^^^^^^^^^^^^^^^^^^^^^^^^^
  File "D:\ASRP-main\asrp\blueprints\report\crime_routes.py", line 34, in add_crime_report
    form = CrimeReportForm()
           ^^^^^^^^^^^^^^^^^
  File "C:\Users\admin\AppData\Local\Programs\Python\Python311\Lib\site-packages\wtforms\form.py", line 209, in __call__
    return type.__call__(cls, *args, **kwargs)
           ^^^^^^^^^^^^^^^^^^^^^^^^^^^^^^^^^^^
  File "D:\ASRP-main\asrp\blueprints\report\CrimeReportForm.py", line 26, in __init__
    self.status_id.choices = [(s.id, s.name) for s in Status.query.all()]
    ^^^^^^^^^^^^^^
AttributeError: 'CrimeReportForm' object has no attribute 'status_id'
[2025-05-04 15:12:45,275] ERROR in app: Exception on /report/crime/add [GET]
Traceback (most recent call last):
  File "C:\Users\admin\AppData\Local\Programs\Python\Python311\Lib\site-packages\flask\app.py", line 2529, in wsgi_app
    response = self.full_dispatch_request()
               ^^^^^^^^^^^^^^^^^^^^^^^^^^^^
  File "C:\Users\admin\AppData\Local\Programs\Python\Python311\Lib\site-packages\flask\app.py", line 1825, in full_dispatch_request
    rv = self.handle_user_exception(e)
         ^^^^^^^^^^^^^^^^^^^^^^^^^^^^^
  File "C:\Users\admin\AppData\Local\Programs\Python\Python311\Lib\site-packages\flask\app.py", line 1823, in full_dispatch_request
    rv = self.dispatch_request()
         ^^^^^^^^^^^^^^^^^^^^^^^
  File "C:\Users\admin\AppData\Local\Programs\Python\Python311\Lib\site-packages\flask\app.py", line 1799, in dispatch_request
    return self.ensure_sync(self.view_functions[rule.endpoint])(**view_args)
           ^^^^^^^^^^^^^^^^^^^^^^^^^^^^^^^^^^^^^^^^^^^^^^^^^^^^^^^^^^^^^^^^^
  File "C:\Users\admin\AppData\Local\Programs\Python\Python311\Lib\site-packages\flask_login\utils.py", line 290, in decorated_view
    return current_app.ensure_sync(func)(*args, **kwargs)
           ^^^^^^^^^^^^^^^^^^^^^^^^^^^^^^^^^^^^^^^^^^^^^^
  File "D:\ASRP-main\asrp\blueprints\report\crime_routes.py", line 34, in add_crime_report
    form = CrimeReportForm()
           ^^^^^^^^^^^^^^^^^
  File "C:\Users\admin\AppData\Local\Programs\Python\Python311\Lib\site-packages\wtforms\form.py", line 209, in __call__
    return type.__call__(cls, *args, **kwargs)
           ^^^^^^^^^^^^^^^^^^^^^^^^^^^^^^^^^^^
  File "D:\ASRP-main\asrp\blueprints\report\CrimeReportForm.py", line 26, in __init__
    self.status_id.choices = [(s.id, s.name) for s in Status.query.all()]
    ^^^^^^^^^^^^^^
AttributeError: 'CrimeReportForm' object has no attribute 'status_id'
[2025-05-07 22:55:45,736] ERROR in app: Exception on /report/statistics [GET]
Traceback (most recent call last):
  File "C:\Users\admin\AppData\Local\Programs\Python\Python311\Lib\site-packages\flask\app.py", line 2529, in wsgi_app
    response = self.full_dispatch_request()
               ^^^^^^^^^^^^^^^^^^^^^^^^^^^^
  File "C:\Users\admin\AppData\Local\Programs\Python\Python311\Lib\site-packages\flask\app.py", line 1825, in full_dispatch_request
    rv = self.handle_user_exception(e)
         ^^^^^^^^^^^^^^^^^^^^^^^^^^^^^
  File "C:\Users\admin\AppData\Local\Programs\Python\Python311\Lib\site-packages\flask\app.py", line 1823, in full_dispatch_request
    rv = self.dispatch_request()
         ^^^^^^^^^^^^^^^^^^^^^^^
  File "C:\Users\admin\AppData\Local\Programs\Python\Python311\Lib\site-packages\flask\app.py", line 1799, in dispatch_request
    return self.ensure_sync(self.view_functions[rule.endpoint])(**view_args)
           ^^^^^^^^^^^^^^^^^^^^^^^^^^^^^^^^^^^^^^^^^^^^^^^^^^^^^^^^^^^^^^^^^
  File "C:\Users\admin\AppData\Local\Programs\Python\Python311\Lib\site-packages\flask_login\utils.py", line 290, in decorated_view
    return current_app.ensure_sync(func)(*args, **kwargs)
           ^^^^^^^^^^^^^^^^^^^^^^^^^^^^^^^^^^^^^^^^^^^^^^
  File "D:\ASRP-main\asrp\blueprints\report\report_views.py", line 55, in report_statistics
    status_stats = db.session.query(model.status, func.count(model.id)).group_by(model.status).all()
                                    ^^^^^^^^^^^^
AttributeError: type object 'CrimeReport' has no attribute 'status'
[2025-05-07 22:55:48,459] ERROR in app: Exception on /report/my_reports [GET]
Traceback (most recent call last):
  File "C:\Users\admin\AppData\Local\Programs\Python\Python311\Lib\site-packages\flask\app.py", line 2529, in wsgi_app
    response = self.full_dispatch_request()
               ^^^^^^^^^^^^^^^^^^^^^^^^^^^^
  File "C:\Users\admin\AppData\Local\Programs\Python\Python311\Lib\site-packages\flask\app.py", line 1825, in full_dispatch_request
    rv = self.handle_user_exception(e)
         ^^^^^^^^^^^^^^^^^^^^^^^^^^^^^
  File "C:\Users\admin\AppData\Local\Programs\Python\Python311\Lib\site-packages\flask\app.py", line 1823, in full_dispatch_request
    rv = self.dispatch_request()
         ^^^^^^^^^^^^^^^^^^^^^^^
  File "C:\Users\admin\AppData\Local\Programs\Python\Python311\Lib\site-packages\flask\app.py", line 1799, in dispatch_request
    return self.ensure_sync(self.view_functions[rule.endpoint])(**view_args)
           ^^^^^^^^^^^^^^^^^^^^^^^^^^^^^^^^^^^^^^^^^^^^^^^^^^^^^^^^^^^^^^^^^
  File "D:\ASRP-main\asrp\blueprints\report\__init__.py", line 27, in my_reports
    crime_reports = CrimeReport.query.all()
                    ^^^^^^^^^^^
NameError: name 'CrimeReport' is not defined
[2025-05-07 23:23:27,920] ERROR in app: Exception on /report/group/add [POST]
Traceback (most recent call last):
  File "D:\ASRP-main\asrp\blueprints\report\group_routes.py", line 31, in add_group_report
    db.session.commit()
  File "C:\Users\admin\AppData\Local\Programs\Python\Python311\Lib\site-packages\sqlalchemy\orm\scoping.py", line 599, in commit
    return self._proxied.commit()
           ^^^^^^^^^^^^^^^^^^^^^^
  File "C:\Users\admin\AppData\Local\Programs\Python\Python311\Lib\site-packages\sqlalchemy\orm\session.py", line 2032, in commit
    trans.commit(_to_root=True)
  File "<string>", line 2, in commit
  File "C:\Users\admin\AppData\Local\Programs\Python\Python311\Lib\site-packages\sqlalchemy\orm\state_changes.py", line 139, in _go
    ret_value = fn(self, *arg, **kw)
                ^^^^^^^^^^^^^^^^^^^^
  File "C:\Users\admin\AppData\Local\Programs\Python\Python311\Lib\site-packages\sqlalchemy\orm\session.py", line 1313, in commit
    self._prepare_impl()
  File "<string>", line 2, in _prepare_impl
  File "C:\Users\admin\AppData\Local\Programs\Python\Python311\Lib\site-packages\sqlalchemy\orm\state_changes.py", line 139, in _go
    ret_value = fn(self, *arg, **kw)
                ^^^^^^^^^^^^^^^^^^^^
  File "C:\Users\admin\AppData\Local\Programs\Python\Python311\Lib\site-packages\sqlalchemy\orm\session.py", line 1288, in _prepare_impl
    self.session.flush()
  File "C:\Users\admin\AppData\Local\Programs\Python\Python311\Lib\site-packages\sqlalchemy\orm\session.py", line 4353, in flush
    self._flush(objects)
  File "C:\Users\admin\AppData\Local\Programs\Python\Python311\Lib\site-packages\sqlalchemy\orm\session.py", line 4488, in _flush
    with util.safe_reraise():
  File "C:\Users\admin\AppData\Local\Programs\Python\Python311\Lib\site-packages\sqlalchemy\util\langhelpers.py", line 146, in __exit__
    raise exc_value.with_traceback(exc_tb)
  File "C:\Users\admin\AppData\Local\Programs\Python\Python311\Lib\site-packages\sqlalchemy\orm\session.py", line 4455, in _flush
    flush_context.finalize_flush_changes()
  File "C:\Users\admin\AppData\Local\Programs\Python\Python311\Lib\site-packages\sqlalchemy\orm\unitofwork.py", line 487, in finalize_flush_changes
    self.session._register_persistent(other)
  File "C:\Users\admin\AppData\Local\Programs\Python\Python311\Lib\site-packages\sqlalchemy\orm\session.py", line 3357, in _register_persistent
    raise exc.FlushError(
sqlalchemy.orm.exc.FlushError: Instance <GroupReport at 0x1e7be2a1250> has a NULL identity key.  If this is an auto-generated value, check that the database table allows generation of new primary key values, and that the mapped Column object is configured to expect these generated values.  Ensure also that this flush() is not occurring at an inappropriate time, such as within a load() event.

During handling of the above exception, another exception occurred:

Traceback (most recent call last):
  File "C:\Users\admin\AppData\Local\Programs\Python\Python311\Lib\site-packages\flask\app.py", line 2529, in wsgi_app
    response = self.full_dispatch_request()
               ^^^^^^^^^^^^^^^^^^^^^^^^^^^^
  File "C:\Users\admin\AppData\Local\Programs\Python\Python311\Lib\site-packages\flask\app.py", line 1825, in full_dispatch_request
    rv = self.handle_user_exception(e)
         ^^^^^^^^^^^^^^^^^^^^^^^^^^^^^
  File "C:\Users\admin\AppData\Local\Programs\Python\Python311\Lib\site-packages\flask\app.py", line 1823, in full_dispatch_request
    rv = self.dispatch_request()
         ^^^^^^^^^^^^^^^^^^^^^^^
  File "C:\Users\admin\AppData\Local\Programs\Python\Python311\Lib\site-packages\flask\app.py", line 1799, in dispatch_request
    return self.ensure_sync(self.view_functions[rule.endpoint])(**view_args)
           ^^^^^^^^^^^^^^^^^^^^^^^^^^^^^^^^^^^^^^^^^^^^^^^^^^^^^^^^^^^^^^^^^
  File "C:\Users\admin\AppData\Local\Programs\Python\Python311\Lib\site-packages\flask_login\utils.py", line 290, in decorated_view
    return current_app.ensure_sync(func)(*args, **kwargs)
           ^^^^^^^^^^^^^^^^^^^^^^^^^^^^^^^^^^^^^^^^^^^^^^
  File "D:\ASRP-main\asrp\blueprints\report\group_routes.py", line 39, in add_group_report
    return redirect(url_for('group.add_group_report'))
                    ^^^^^^^^^^^^^^^^^^^^^^^^^^^^^^^^^
  File "C:\Users\admin\AppData\Local\Programs\Python\Python311\Lib\site-packages\flask\helpers.py", line 256, in url_for
    return current_app.url_for(
           ^^^^^^^^^^^^^^^^^^^^
  File "C:\Users\admin\AppData\Local\Programs\Python\Python311\Lib\site-packages\flask\app.py", line 2034, in url_for
    return self.handle_url_build_error(error, endpoint, values)
           ^^^^^^^^^^^^^^^^^^^^^^^^^^^^^^^^^^^^^^^^^^^^^^^^^^^^
  File "C:\Users\admin\AppData\Local\Programs\Python\Python311\Lib\site-packages\flask\app.py", line 2023, in url_for
    rv = url_adapter.build(  # type: ignore[union-attr]
         ^^^^^^^^^^^^^^^^^^^^^^^^^^^^^^^^^^^^^^^^^^^^^^
  File "C:\Users\admin\AppData\Local\Programs\Python\Python311\Lib\site-packages\werkzeug\routing\map.py", line 924, in build
    raise BuildError(endpoint, values, method, self)
werkzeug.routing.exceptions.BuildError: Could not build url for endpoint 'group.add_group_report'. Did you mean 'report.group.add_group_report' instead?
[2025-05-08 00:22:01,882] ERROR in app: Exception on /report/statistics [GET]
Traceback (most recent call last):
  File "C:\Users\admin\AppData\Local\Programs\Python\Python311\Lib\site-packages\flask\app.py", line 2529, in wsgi_app
    response = self.full_dispatch_request()
               ^^^^^^^^^^^^^^^^^^^^^^^^^^^^
  File "C:\Users\admin\AppData\Local\Programs\Python\Python311\Lib\site-packages\flask\app.py", line 1825, in full_dispatch_request
    rv = self.handle_user_exception(e)
         ^^^^^^^^^^^^^^^^^^^^^^^^^^^^^
  File "C:\Users\admin\AppData\Local\Programs\Python\Python311\Lib\site-packages\flask\app.py", line 1823, in full_dispatch_request
    rv = self.dispatch_request()
         ^^^^^^^^^^^^^^^^^^^^^^^
  File "C:\Users\admin\AppData\Local\Programs\Python\Python311\Lib\site-packages\flask\app.py", line 1799, in dispatch_request
    return self.ensure_sync(self.view_functions[rule.endpoint])(**view_args)
           ^^^^^^^^^^^^^^^^^^^^^^^^^^^^^^^^^^^^^^^^^^^^^^^^^^^^^^^^^^^^^^^^^
  File "C:\Users\admin\AppData\Local\Programs\Python\Python311\Lib\site-packages\flask_login\utils.py", line 290, in decorated_view
    return current_app.ensure_sync(func)(*args, **kwargs)
           ^^^^^^^^^^^^^^^^^^^^^^^^^^^^^^^^^^^^^^^^^^^^^^
  File "D:\ASRP-main\asrp\blueprints\report\report_views.py", line 55, in report_statistics
    status_stats = db.session.query(model.status, func.count(model.id)).group_by(model.status).all()
                                    ^^^^^^^^^^^^
AttributeError: type object 'CrimeReport' has no attribute 'status'
[2025-05-08 00:22:04,792] ERROR in app: Exception on /report/my_reports [GET]
Traceback (most recent call last):
  File "C:\Users\admin\AppData\Local\Programs\Python\Python311\Lib\site-packages\flask\app.py", line 2529, in wsgi_app
    response = self.full_dispatch_request()
               ^^^^^^^^^^^^^^^^^^^^^^^^^^^^
  File "C:\Users\admin\AppData\Local\Programs\Python\Python311\Lib\site-packages\flask\app.py", line 1825, in full_dispatch_request
    rv = self.handle_user_exception(e)
         ^^^^^^^^^^^^^^^^^^^^^^^^^^^^^
  File "C:\Users\admin\AppData\Local\Programs\Python\Python311\Lib\site-packages\flask\app.py", line 1823, in full_dispatch_request
    rv = self.dispatch_request()
         ^^^^^^^^^^^^^^^^^^^^^^^
  File "C:\Users\admin\AppData\Local\Programs\Python\Python311\Lib\site-packages\flask\app.py", line 1799, in dispatch_request
    return self.ensure_sync(self.view_functions[rule.endpoint])(**view_args)
           ^^^^^^^^^^^^^^^^^^^^^^^^^^^^^^^^^^^^^^^^^^^^^^^^^^^^^^^^^^^^^^^^^
  File "D:\ASRP-main\asrp\blueprints\report\__init__.py", line 27, in my_reports
    crime_reports = CrimeReport.query.all()
                    ^^^^^^^^^^^
NameError: name 'CrimeReport' is not defined
[2025-05-10 23:04:38,795] ERROR in app: Exception on /report/extraction/add [POST]
Traceback (most recent call last):
  File "C:\Users\admin\AppData\Local\Programs\Python\Python311\Lib\site-packages\flask\app.py", line 2529, in wsgi_app
    response = self.full_dispatch_request()
               ^^^^^^^^^^^^^^^^^^^^^^^^^^^^
  File "C:\Users\admin\AppData\Local\Programs\Python\Python311\Lib\site-packages\flask\app.py", line 1825, in full_dispatch_request
    rv = self.handle_user_exception(e)
         ^^^^^^^^^^^^^^^^^^^^^^^^^^^^^
  File "C:\Users\admin\AppData\Local\Programs\Python\Python311\Lib\site-packages\flask\app.py", line 1823, in full_dispatch_request
    rv = self.dispatch_request()
         ^^^^^^^^^^^^^^^^^^^^^^^
  File "C:\Users\admin\AppData\Local\Programs\Python\Python311\Lib\site-packages\flask\app.py", line 1799, in dispatch_request
    return self.ensure_sync(self.view_functions[rule.endpoint])(**view_args)
           ^^^^^^^^^^^^^^^^^^^^^^^^^^^^^^^^^^^^^^^^^^^^^^^^^^^^^^^^^^^^^^^^^
  File "C:\Users\admin\AppData\Local\Programs\Python\Python311\Lib\site-packages\flask_login\utils.py", line 290, in decorated_view
    return current_app.ensure_sync(func)(*args, **kwargs)
           ^^^^^^^^^^^^^^^^^^^^^^^^^^^^^^^^^^^^^^^^^^^^^^
  File "D:\ASRP-main\asrp\blueprints\report\extraction_routes.py", line 40, in add_extraction_request
    form = ExtractionRequestForm()
           ^^^^^^^^^^^^^^^^^^^^^^^
  File "C:\Users\admin\AppData\Local\Programs\Python\Python311\Lib\site-packages\wtforms\form.py", line 209, in __call__
    return type.__call__(cls, *args, **kwargs)
           ^^^^^^^^^^^^^^^^^^^^^^^^^^^^^^^^^^^
  File "D:\ASRP-main\asrp\blueprints\report\ExtractionRequestForm.py", line 22, in __init__
    self.status_id.data = 1
    ^^^^^^^^^^^^^^
AttributeError: 'ExtractionRequestForm' object has no attribute 'status_id'
[2025-05-10 23:08:38,869] ERROR in app: Exception on /report/extraction/add [GET]
Traceback (most recent call last):
  File "C:\Users\admin\AppData\Local\Programs\Python\Python311\Lib\site-packages\flask\app.py", line 2529, in wsgi_app
    response = self.full_dispatch_request()
               ^^^^^^^^^^^^^^^^^^^^^^^^^^^^
  File "C:\Users\admin\AppData\Local\Programs\Python\Python311\Lib\site-packages\flask\app.py", line 1825, in full_dispatch_request
    rv = self.handle_user_exception(e)
         ^^^^^^^^^^^^^^^^^^^^^^^^^^^^^
  File "C:\Users\admin\AppData\Local\Programs\Python\Python311\Lib\site-packages\flask\app.py", line 1823, in full_dispatch_request
    rv = self.dispatch_request()
         ^^^^^^^^^^^^^^^^^^^^^^^
  File "C:\Users\admin\AppData\Local\Programs\Python\Python311\Lib\site-packages\flask\app.py", line 1799, in dispatch_request
    return self.ensure_sync(self.view_functions[rule.endpoint])(**view_args)
           ^^^^^^^^^^^^^^^^^^^^^^^^^^^^^^^^^^^^^^^^^^^^^^^^^^^^^^^^^^^^^^^^^
  File "C:\Users\admin\AppData\Local\Programs\Python\Python311\Lib\site-packages\flask_login\utils.py", line 290, in decorated_view
    return current_app.ensure_sync(func)(*args, **kwargs)
           ^^^^^^^^^^^^^^^^^^^^^^^^^^^^^^^^^^^^^^^^^^^^^^
  File "D:\ASRP-main\asrp\blueprints\report\extraction_routes.py", line 40, in add_extraction_request
    form = ExtractionRequestForm()
           ^^^^^^^^^^^^^^^^^^^^^^^
  File "C:\Users\admin\AppData\Local\Programs\Python\Python311\Lib\site-packages\wtforms\form.py", line 209, in __call__
    return type.__call__(cls, *args, **kwargs)
           ^^^^^^^^^^^^^^^^^^^^^^^^^^^^^^^^^^^
  File "D:\ASRP-main\asrp\blueprints\report\ExtractionRequestForm.py", line 22, in __init__
    self.status_id.data = 1
    ^^^^^^^^^^^^^^
AttributeError: 'ExtractionRequestForm' object has no attribute 'status_id'
[2025-05-10 23:09:25,728] ERROR in app: Exception on /report/extraction/add [GET]
Traceback (most recent call last):
  File "C:\Users\admin\AppData\Local\Programs\Python\Python311\Lib\site-packages\flask\app.py", line 2529, in wsgi_app
    response = self.full_dispatch_request()
               ^^^^^^^^^^^^^^^^^^^^^^^^^^^^
  File "C:\Users\admin\AppData\Local\Programs\Python\Python311\Lib\site-packages\flask\app.py", line 1825, in full_dispatch_request
    rv = self.handle_user_exception(e)
         ^^^^^^^^^^^^^^^^^^^^^^^^^^^^^
  File "C:\Users\admin\AppData\Local\Programs\Python\Python311\Lib\site-packages\flask\app.py", line 1823, in full_dispatch_request
    rv = self.dispatch_request()
         ^^^^^^^^^^^^^^^^^^^^^^^
  File "C:\Users\admin\AppData\Local\Programs\Python\Python311\Lib\site-packages\flask\app.py", line 1799, in dispatch_request
    return self.ensure_sync(self.view_functions[rule.endpoint])(**view_args)
           ^^^^^^^^^^^^^^^^^^^^^^^^^^^^^^^^^^^^^^^^^^^^^^^^^^^^^^^^^^^^^^^^^
  File "C:\Users\admin\AppData\Local\Programs\Python\Python311\Lib\site-packages\flask_login\utils.py", line 290, in decorated_view
    return current_app.ensure_sync(func)(*args, **kwargs)
           ^^^^^^^^^^^^^^^^^^^^^^^^^^^^^^^^^^^^^^^^^^^^^^
  File "D:\ASRP-main\asrp\blueprints\report\extraction_routes.py", line 40, in add_extraction_request
    form = ExtractionRequestForm()
           ^^^^^^^^^^^^^^^^^^^^^^^
  File "C:\Users\admin\AppData\Local\Programs\Python\Python311\Lib\site-packages\wtforms\form.py", line 209, in __call__
    return type.__call__(cls, *args, **kwargs)
           ^^^^^^^^^^^^^^^^^^^^^^^^^^^^^^^^^^^
  File "D:\ASRP-main\asrp\blueprints\report\ExtractionRequestForm.py", line 23, in __init__
    self.category_id.data = 4
    ^^^^^^^^^^^^^^^^
AttributeError: 'ExtractionRequestForm' object has no attribute 'category_id'
[2025-05-10 23:10:00,787] ERROR in app: Exception on /report/extraction/add [GET]
Traceback (most recent call last):
  File "C:\Users\admin\AppData\Local\Programs\Python\Python311\Lib\site-packages\flask\app.py", line 2529, in wsgi_app
    response = self.full_dispatch_request()
               ^^^^^^^^^^^^^^^^^^^^^^^^^^^^
  File "C:\Users\admin\AppData\Local\Programs\Python\Python311\Lib\site-packages\flask\app.py", line 1825, in full_dispatch_request
    rv = self.handle_user_exception(e)
         ^^^^^^^^^^^^^^^^^^^^^^^^^^^^^
  File "C:\Users\admin\AppData\Local\Programs\Python\Python311\Lib\site-packages\flask\app.py", line 1823, in full_dispatch_request
    rv = self.dispatch_request()
         ^^^^^^^^^^^^^^^^^^^^^^^
  File "C:\Users\admin\AppData\Local\Programs\Python\Python311\Lib\site-packages\flask\app.py", line 1799, in dispatch_request
    return self.ensure_sync(self.view_functions[rule.endpoint])(**view_args)
           ^^^^^^^^^^^^^^^^^^^^^^^^^^^^^^^^^^^^^^^^^^^^^^^^^^^^^^^^^^^^^^^^^
  File "C:\Users\admin\AppData\Local\Programs\Python\Python311\Lib\site-packages\flask_login\utils.py", line 290, in decorated_view
    return current_app.ensure_sync(func)(*args, **kwargs)
           ^^^^^^^^^^^^^^^^^^^^^^^^^^^^^^^^^^^^^^^^^^^^^^
  File "D:\ASRP-main\asrp\blueprints\report\extraction_routes.py", line 40, in add_extraction_request
    form = ExtractionRequestForm()
           ^^^^^^^^^^^^^^^^^^^^^^^
  File "C:\Users\admin\AppData\Local\Programs\Python\Python311\Lib\site-packages\wtforms\form.py", line 209, in __call__
    return type.__call__(cls, *args, **kwargs)
           ^^^^^^^^^^^^^^^^^^^^^^^^^^^^^^^^^^^
  File "D:\ASRP-main\asrp\blueprints\report\ExtractionRequestForm.py", line 23, in __init__
    self.category_id.data = 4
    ^^^^^^^^^^^^^^^^
AttributeError: 'ExtractionRequestForm' object has no attribute 'category_id'
[2025-05-10 23:10:10,029] ERROR in app: Exception on /report/extraction/add [GET]
Traceback (most recent call last):
  File "C:\Users\admin\AppData\Local\Programs\Python\Python311\Lib\site-packages\flask\app.py", line 2529, in wsgi_app
    response = self.full_dispatch_request()
               ^^^^^^^^^^^^^^^^^^^^^^^^^^^^
  File "C:\Users\admin\AppData\Local\Programs\Python\Python311\Lib\site-packages\flask\app.py", line 1825, in full_dispatch_request
    rv = self.handle_user_exception(e)
         ^^^^^^^^^^^^^^^^^^^^^^^^^^^^^
  File "C:\Users\admin\AppData\Local\Programs\Python\Python311\Lib\site-packages\flask\app.py", line 1823, in full_dispatch_request
    rv = self.dispatch_request()
         ^^^^^^^^^^^^^^^^^^^^^^^
  File "C:\Users\admin\AppData\Local\Programs\Python\Python311\Lib\site-packages\flask\app.py", line 1799, in dispatch_request
    return self.ensure_sync(self.view_functions[rule.endpoint])(**view_args)
           ^^^^^^^^^^^^^^^^^^^^^^^^^^^^^^^^^^^^^^^^^^^^^^^^^^^^^^^^^^^^^^^^^
  File "C:\Users\admin\AppData\Local\Programs\Python\Python311\Lib\site-packages\flask_login\utils.py", line 290, in decorated_view
    return current_app.ensure_sync(func)(*args, **kwargs)
           ^^^^^^^^^^^^^^^^^^^^^^^^^^^^^^^^^^^^^^^^^^^^^^
  File "D:\ASRP-main\asrp\blueprints\report\extraction_routes.py", line 40, in add_extraction_request
    form = ExtractionRequestForm()
           ^^^^^^^^^^^^^^^^^^^^^^^
  File "C:\Users\admin\AppData\Local\Programs\Python\Python311\Lib\site-packages\wtforms\form.py", line 209, in __call__
    return type.__call__(cls, *args, **kwargs)
           ^^^^^^^^^^^^^^^^^^^^^^^^^^^^^^^^^^^
  File "D:\ASRP-main\asrp\blueprints\report\ExtractionRequestForm.py", line 23, in __init__
    self.category_id.data = 4
    ^^^^^^^^^^^^^^^^
AttributeError: 'ExtractionRequestForm' object has no attribute 'category_id'
[2025-05-10 23:13:56,555] ERROR in app: Exception on /report/extraction/add [POST]
Traceback (most recent call last):
  File "C:\Users\admin\AppData\Local\Programs\Python\Python311\Lib\site-packages\flask\app.py", line 2529, in wsgi_app
    response = self.full_dispatch_request()
               ^^^^^^^^^^^^^^^^^^^^^^^^^^^^
  File "C:\Users\admin\AppData\Local\Programs\Python\Python311\Lib\site-packages\flask\app.py", line 1825, in full_dispatch_request
    rv = self.handle_user_exception(e)
         ^^^^^^^^^^^^^^^^^^^^^^^^^^^^^
  File "C:\Users\admin\AppData\Local\Programs\Python\Python311\Lib\site-packages\flask\app.py", line 1823, in full_dispatch_request
    rv = self.dispatch_request()
         ^^^^^^^^^^^^^^^^^^^^^^^
  File "C:\Users\admin\AppData\Local\Programs\Python\Python311\Lib\site-packages\flask\app.py", line 1799, in dispatch_request
    return self.ensure_sync(self.view_functions[rule.endpoint])(**view_args)
           ^^^^^^^^^^^^^^^^^^^^^^^^^^^^^^^^^^^^^^^^^^^^^^^^^^^^^^^^^^^^^^^^^
  File "C:\Users\admin\AppData\Local\Programs\Python\Python311\Lib\site-packages\flask_login\utils.py", line 290, in decorated_view
    return current_app.ensure_sync(func)(*args, **kwargs)
           ^^^^^^^^^^^^^^^^^^^^^^^^^^^^^^^^^^^^^^^^^^^^^^
  File "D:\ASRP-main\asrp\blueprints\report\extraction_routes.py", line 42, in add_extraction_request
    if request.method == 'POST' and form.validate_on_submit():
                                    ^^^^^^^^^^^^^^^^^^^^^^^^^
  File "C:\Users\admin\AppData\Local\Programs\Python\Python311\Lib\site-packages\flask_wtf\form.py", line 86, in validate_on_submit
    return self.is_submitted() and self.validate(extra_validators=extra_validators)
                                   ^^^^^^^^^^^^^^^^^^^^^^^^^^^^^^^^^^^^^^^^^^^^^^^^
  File "C:\Users\admin\AppData\Local\Programs\Python\Python311\Lib\site-packages\wtforms\form.py", line 330, in validate
    return super().validate(extra)
           ^^^^^^^^^^^^^^^^^^^^^^^
  File "C:\Users\admin\AppData\Local\Programs\Python\Python311\Lib\site-packages\wtforms\form.py", line 147, in validate
    if not field.validate(self, extra):
           ^^^^^^^^^^^^^^^^^^^^^^^^^^^
  File "C:\Users\admin\AppData\Local\Programs\Python\Python311\Lib\site-packages\wtforms\fields\core.py", line 223, in validate
    self.pre_validate(form)
  File "C:\Users\admin\AppData\Local\Programs\Python\Python311\Lib\site-packages\wtforms\fields\choices.py", line 149, in pre_validate
    raise TypeError(self.gettext("Choices cannot be None."))
TypeError: Choices cannot be None.
[2025-05-10 23:22:25,932] ERROR in app: Exception on /admin/status/edit/ [GET]
Traceback (most recent call last):
  File "C:\Users\admin\AppData\Local\Programs\Python\Python311\Lib\site-packages\flask\app.py", line 2529, in wsgi_app
    response = self.full_dispatch_request()
               ^^^^^^^^^^^^^^^^^^^^^^^^^^^^
  File "C:\Users\admin\AppData\Local\Programs\Python\Python311\Lib\site-packages\flask\app.py", line 1825, in full_dispatch_request
    rv = self.handle_user_exception(e)
         ^^^^^^^^^^^^^^^^^^^^^^^^^^^^^
  File "C:\Users\admin\AppData\Local\Programs\Python\Python311\Lib\site-packages\flask\app.py", line 1823, in full_dispatch_request
    rv = self.dispatch_request()
         ^^^^^^^^^^^^^^^^^^^^^^^
  File "C:\Users\admin\AppData\Local\Programs\Python\Python311\Lib\site-packages\flask\app.py", line 1799, in dispatch_request
    return self.ensure_sync(self.view_functions[rule.endpoint])(**view_args)
           ^^^^^^^^^^^^^^^^^^^^^^^^^^^^^^^^^^^^^^^^^^^^^^^^^^^^^^^^^^^^^^^^^
  File "C:\Users\admin\AppData\Local\Programs\Python\Python311\Lib\site-packages\flask_admin\base.py", line 69, in inner
    return self._run_view(f, *args, **kwargs)
           ^^^^^^^^^^^^^^^^^^^^^^^^^^^^^^^^^^
  File "C:\Users\admin\AppData\Local\Programs\Python\Python311\Lib\site-packages\flask_admin\base.py", line 369, in _run_view
    return fn(self, *args, **kwargs)
           ^^^^^^^^^^^^^^^^^^^^^^^^^
  File "C:\Users\admin\AppData\Local\Programs\Python\Python311\Lib\site-packages\flask_admin\model\base.py", line 2149, in edit_view
    form = self.edit_form(obj=model)
           ^^^^^^^^^^^^^^^^^^^^^^^^^
  File "C:\Users\admin\AppData\Local\Programs\Python\Python311\Lib\site-packages\flask_admin\model\base.py", line 1340, in edit_form
    return self._edit_form_class(get_form_data(), obj=obj)
           ^^^^^^^^^^^^^^^^^^^^^^^^^^^^^^^^^^^^^^^^^^^^^^^
  File "C:\Users\admin\AppData\Local\Programs\Python\Python311\Lib\site-packages\wtforms\form.py", line 209, in __call__
    return type.__call__(cls, *args, **kwargs)
           ^^^^^^^^^^^^^^^^^^^^^^^^^^^^^^^^^^^
  File "C:\Users\admin\AppData\Local\Programs\Python\Python311\Lib\site-packages\flask_admin\form\__init__.py", line 22, in __init__
    super(BaseForm, self).__init__(formdata=formdata, obj=obj, prefix=prefix, **kwargs)
  File "C:\Users\admin\AppData\Local\Programs\Python\Python311\Lib\site-packages\wtforms\form.py", line 281, in __init__
    super().__init__(self._unbound_fields, meta=meta_obj, prefix=prefix)
  File "C:\Users\admin\AppData\Local\Programs\Python\Python311\Lib\site-packages\wtforms\form.py", line 49, in __init__
    field = meta.bind_field(self, unbound_field, options)
            ^^^^^^^^^^^^^^^^^^^^^^^^^^^^^^^^^^^^^^^^^^^^^
  File "C:\Users\admin\AppData\Local\Programs\Python\Python311\Lib\site-packages\wtforms\meta.py", line 28, in bind_field
    return unbound_field.bind(form=form, **options)
           ^^^^^^^^^^^^^^^^^^^^^^^^^^^^^^^^^^^^^^^^
  File "C:\Users\admin\AppData\Local\Programs\Python\Python311\Lib\site-packages\wtforms\fields\core.py", line 387, in bind
    return self.field_class(*self.args, **kw)
           ^^^^^^^^^^^^^^^^^^^^^^^^^^^^^^^^^^
  File "C:\Users\admin\AppData\Local\Programs\Python\Python311\Lib\site-packages\wtforms\fields\core.py", line 133, in __init__
    for k, v in flags.items():
                ^^^^^^^^^^^
AttributeError: 'tuple' object has no attribute 'items'
[2025-05-10 23:23:32,679] ERROR in app: Exception on /report/statistics [GET]
Traceback (most recent call last):
  File "C:\Users\admin\AppData\Local\Programs\Python\Python311\Lib\site-packages\flask\app.py", line 2529, in wsgi_app
    response = self.full_dispatch_request()
               ^^^^^^^^^^^^^^^^^^^^^^^^^^^^
  File "C:\Users\admin\AppData\Local\Programs\Python\Python311\Lib\site-packages\flask\app.py", line 1825, in full_dispatch_request
    rv = self.handle_user_exception(e)
         ^^^^^^^^^^^^^^^^^^^^^^^^^^^^^
  File "C:\Users\admin\AppData\Local\Programs\Python\Python311\Lib\site-packages\flask\app.py", line 1823, in full_dispatch_request
    rv = self.dispatch_request()
         ^^^^^^^^^^^^^^^^^^^^^^^
  File "C:\Users\admin\AppData\Local\Programs\Python\Python311\Lib\site-packages\flask\app.py", line 1799, in dispatch_request
    return self.ensure_sync(self.view_functions[rule.endpoint])(**view_args)
           ^^^^^^^^^^^^^^^^^^^^^^^^^^^^^^^^^^^^^^^^^^^^^^^^^^^^^^^^^^^^^^^^^
  File "C:\Users\admin\AppData\Local\Programs\Python\Python311\Lib\site-packages\flask_login\utils.py", line 290, in decorated_view
    return current_app.ensure_sync(func)(*args, **kwargs)
           ^^^^^^^^^^^^^^^^^^^^^^^^^^^^^^^^^^^^^^^^^^^^^^
  File "D:\ASRP-main\asrp\blueprints\report\report_views.py", line 55, in report_statistics
    status_stats = db.session.query(model.status, func.count(model.id)).group_by(model.status).all()
                                    ^^^^^^^^^^^^
AttributeError: type object 'CrimeReport' has no attribute 'status'
[2025-05-10 23:40:09,109] ERROR in app: Exception on /report/statistics [GET]
Traceback (most recent call last):
  File "C:\Users\admin\AppData\Local\Programs\Python\Python311\Lib\site-packages\flask\app.py", line 2529, in wsgi_app
    response = self.full_dispatch_request()
               ^^^^^^^^^^^^^^^^^^^^^^^^^^^^
  File "C:\Users\admin\AppData\Local\Programs\Python\Python311\Lib\site-packages\flask\app.py", line 1825, in full_dispatch_request
    rv = self.handle_user_exception(e)
         ^^^^^^^^^^^^^^^^^^^^^^^^^^^^^
  File "C:\Users\admin\AppData\Local\Programs\Python\Python311\Lib\site-packages\flask\app.py", line 1823, in full_dispatch_request
    rv = self.dispatch_request()
         ^^^^^^^^^^^^^^^^^^^^^^^
  File "C:\Users\admin\AppData\Local\Programs\Python\Python311\Lib\site-packages\flask\app.py", line 1799, in dispatch_request
    return self.ensure_sync(self.view_functions[rule.endpoint])(**view_args)
           ^^^^^^^^^^^^^^^^^^^^^^^^^^^^^^^^^^^^^^^^^^^^^^^^^^^^^^^^^^^^^^^^^
  File "C:\Users\admin\AppData\Local\Programs\Python\Python311\Lib\site-packages\flask_login\utils.py", line 290, in decorated_view
    return current_app.ensure_sync(func)(*args, **kwargs)
           ^^^^^^^^^^^^^^^^^^^^^^^^^^^^^^^^^^^^^^^^^^^^^^
  File "D:\ASRP-main\asrp\blueprints\report\report_views.py", line 55, in report_statistics
    status_stats = db.session.query(model.status, func.count(model.id)).group_by(model.status).all()
                                    ^^^^^^^^^^^^
AttributeError: type object 'CrimeReport' has no attribute 'status'
[2025-05-10 23:40:11,498] ERROR in app: Exception on /report/my_reports [GET]
Traceback (most recent call last):
  File "C:\Users\admin\AppData\Local\Programs\Python\Python311\Lib\site-packages\flask\app.py", line 2529, in wsgi_app
    response = self.full_dispatch_request()
               ^^^^^^^^^^^^^^^^^^^^^^^^^^^^
  File "C:\Users\admin\AppData\Local\Programs\Python\Python311\Lib\site-packages\flask\app.py", line 1825, in full_dispatch_request
    rv = self.handle_user_exception(e)
         ^^^^^^^^^^^^^^^^^^^^^^^^^^^^^
  File "C:\Users\admin\AppData\Local\Programs\Python\Python311\Lib\site-packages\flask\app.py", line 1823, in full_dispatch_request
    rv = self.dispatch_request()
         ^^^^^^^^^^^^^^^^^^^^^^^
  File "C:\Users\admin\AppData\Local\Programs\Python\Python311\Lib\site-packages\flask\app.py", line 1799, in dispatch_request
    return self.ensure_sync(self.view_functions[rule.endpoint])(**view_args)
           ^^^^^^^^^^^^^^^^^^^^^^^^^^^^^^^^^^^^^^^^^^^^^^^^^^^^^^^^^^^^^^^^^
  File "D:\ASRP-main\asrp\blueprints\report\__init__.py", line 27, in my_reports
    crime_reports = CrimeReport.query.all()
                    ^^^^^^^^^^^
NameError: name 'CrimeReport' is not defined
[2025-05-10 23:44:26,376] ERROR in app: Exception on /report/statistics [GET]
Traceback (most recent call last):
  File "C:\Users\admin\AppData\Local\Programs\Python\Python311\Lib\site-packages\flask\app.py", line 2529, in wsgi_app
    response = self.full_dispatch_request()
               ^^^^^^^^^^^^^^^^^^^^^^^^^^^^
  File "C:\Users\admin\AppData\Local\Programs\Python\Python311\Lib\site-packages\flask\app.py", line 1825, in full_dispatch_request
    rv = self.handle_user_exception(e)
         ^^^^^^^^^^^^^^^^^^^^^^^^^^^^^
  File "C:\Users\admin\AppData\Local\Programs\Python\Python311\Lib\site-packages\flask\app.py", line 1823, in full_dispatch_request
    rv = self.dispatch_request()
         ^^^^^^^^^^^^^^^^^^^^^^^
  File "C:\Users\admin\AppData\Local\Programs\Python\Python311\Lib\site-packages\flask\app.py", line 1799, in dispatch_request
    return self.ensure_sync(self.view_functions[rule.endpoint])(**view_args)
           ^^^^^^^^^^^^^^^^^^^^^^^^^^^^^^^^^^^^^^^^^^^^^^^^^^^^^^^^^^^^^^^^^
  File "C:\Users\admin\AppData\Local\Programs\Python\Python311\Lib\site-packages\flask_login\utils.py", line 290, in decorated_view
    return current_app.ensure_sync(func)(*args, **kwargs)
           ^^^^^^^^^^^^^^^^^^^^^^^^^^^^^^^^^^^^^^^^^^^^^^
  File "D:\ASRP-main\asrp\blueprints\report\report_views.py", line 55, in report_statistics
    status_stats = db.session.query(model.status, func.count(model.id)).group_by(model.status).all()
                                    ^^^^^^^^^^^^
AttributeError: type object 'CrimeReport' has no attribute 'status'
[2025-05-10 23:46:46,512] ERROR in app: Exception on /report/statistics [GET]
Traceback (most recent call last):
  File "C:\Users\admin\AppData\Local\Programs\Python\Python311\Lib\site-packages\flask\app.py", line 2529, in wsgi_app
    response = self.full_dispatch_request()
               ^^^^^^^^^^^^^^^^^^^^^^^^^^^^
  File "C:\Users\admin\AppData\Local\Programs\Python\Python311\Lib\site-packages\flask\app.py", line 1825, in full_dispatch_request
    rv = self.handle_user_exception(e)
         ^^^^^^^^^^^^^^^^^^^^^^^^^^^^^
  File "C:\Users\admin\AppData\Local\Programs\Python\Python311\Lib\site-packages\flask\app.py", line 1823, in full_dispatch_request
    rv = self.dispatch_request()
         ^^^^^^^^^^^^^^^^^^^^^^^
  File "C:\Users\admin\AppData\Local\Programs\Python\Python311\Lib\site-packages\flask\app.py", line 1799, in dispatch_request
    return self.ensure_sync(self.view_functions[rule.endpoint])(**view_args)
           ^^^^^^^^^^^^^^^^^^^^^^^^^^^^^^^^^^^^^^^^^^^^^^^^^^^^^^^^^^^^^^^^^
  File "C:\Users\admin\AppData\Local\Programs\Python\Python311\Lib\site-packages\flask_login\utils.py", line 290, in decorated_view
    return current_app.ensure_sync(func)(*args, **kwargs)
           ^^^^^^^^^^^^^^^^^^^^^^^^^^^^^^^^^^^^^^^^^^^^^^
  File "D:\ASRP-main\asrp\blueprints\report\report_views.py", line 55, in report_statistics
    status_stats = db.session.query(model.status, func.count(model.id)).group_by(model.status).all()
                                    ^^^^^^^^^^^^
AttributeError: type object 'CrimeReport' has no attribute 'status'
[2025-05-10 23:47:14,645] ERROR in app: Exception on /report/my_reports [GET]
Traceback (most recent call last):
  File "C:\Users\admin\AppData\Local\Programs\Python\Python311\Lib\site-packages\flask\app.py", line 2529, in wsgi_app
    response = self.full_dispatch_request()
               ^^^^^^^^^^^^^^^^^^^^^^^^^^^^
  File "C:\Users\admin\AppData\Local\Programs\Python\Python311\Lib\site-packages\flask\app.py", line 1825, in full_dispatch_request
    rv = self.handle_user_exception(e)
         ^^^^^^^^^^^^^^^^^^^^^^^^^^^^^
  File "C:\Users\admin\AppData\Local\Programs\Python\Python311\Lib\site-packages\flask\app.py", line 1823, in full_dispatch_request
    rv = self.dispatch_request()
         ^^^^^^^^^^^^^^^^^^^^^^^
  File "C:\Users\admin\AppData\Local\Programs\Python\Python311\Lib\site-packages\flask\app.py", line 1799, in dispatch_request
    return self.ensure_sync(self.view_functions[rule.endpoint])(**view_args)
           ^^^^^^^^^^^^^^^^^^^^^^^^^^^^^^^^^^^^^^^^^^^^^^^^^^^^^^^^^^^^^^^^^
  File "D:\ASRP-main\asrp\blueprints\report\__init__.py", line 27, in my_reports
    crime_reports = CrimeReport.query.all()
                    ^^^^^^^^^^^
NameError: name 'CrimeReport' is not defined
[2025-05-10 23:47:17,092] ERROR in app: Exception on /report/statistics [GET]
Traceback (most recent call last):
  File "C:\Users\admin\AppData\Local\Programs\Python\Python311\Lib\site-packages\flask\app.py", line 2529, in wsgi_app
    response = self.full_dispatch_request()
               ^^^^^^^^^^^^^^^^^^^^^^^^^^^^
  File "C:\Users\admin\AppData\Local\Programs\Python\Python311\Lib\site-packages\flask\app.py", line 1825, in full_dispatch_request
    rv = self.handle_user_exception(e)
         ^^^^^^^^^^^^^^^^^^^^^^^^^^^^^
  File "C:\Users\admin\AppData\Local\Programs\Python\Python311\Lib\site-packages\flask\app.py", line 1823, in full_dispatch_request
    rv = self.dispatch_request()
         ^^^^^^^^^^^^^^^^^^^^^^^
  File "C:\Users\admin\AppData\Local\Programs\Python\Python311\Lib\site-packages\flask\app.py", line 1799, in dispatch_request
    return self.ensure_sync(self.view_functions[rule.endpoint])(**view_args)
           ^^^^^^^^^^^^^^^^^^^^^^^^^^^^^^^^^^^^^^^^^^^^^^^^^^^^^^^^^^^^^^^^^
  File "C:\Users\admin\AppData\Local\Programs\Python\Python311\Lib\site-packages\flask_login\utils.py", line 290, in decorated_view
    return current_app.ensure_sync(func)(*args, **kwargs)
           ^^^^^^^^^^^^^^^^^^^^^^^^^^^^^^^^^^^^^^^^^^^^^^
  File "D:\ASRP-main\asrp\blueprints\report\report_views.py", line 55, in report_statistics
    status_stats = db.session.query(model.status, func.count(model.id)).group_by(model.status).all()
                                    ^^^^^^^^^^^^
AttributeError: type object 'CrimeReport' has no attribute 'status'
[2025-05-11 00:04:17,349] ERROR in app: Exception on /report/statistics [GET]
Traceback (most recent call last):
  File "C:\Users\admin\AppData\Local\Programs\Python\Python311\Lib\site-packages\flask\app.py", line 2529, in wsgi_app
    response = self.full_dispatch_request()
               ^^^^^^^^^^^^^^^^^^^^^^^^^^^^
  File "C:\Users\admin\AppData\Local\Programs\Python\Python311\Lib\site-packages\flask\app.py", line 1825, in full_dispatch_request
    rv = self.handle_user_exception(e)
         ^^^^^^^^^^^^^^^^^^^^^^^^^^^^^
  File "C:\Users\admin\AppData\Local\Programs\Python\Python311\Lib\site-packages\flask\app.py", line 1823, in full_dispatch_request
    rv = self.dispatch_request()
         ^^^^^^^^^^^^^^^^^^^^^^^
  File "C:\Users\admin\AppData\Local\Programs\Python\Python311\Lib\site-packages\flask\app.py", line 1799, in dispatch_request
    return self.ensure_sync(self.view_functions[rule.endpoint])(**view_args)
           ^^^^^^^^^^^^^^^^^^^^^^^^^^^^^^^^^^^^^^^^^^^^^^^^^^^^^^^^^^^^^^^^^
  File "C:\Users\admin\AppData\Local\Programs\Python\Python311\Lib\site-packages\flask_login\utils.py", line 290, in decorated_view
    return current_app.ensure_sync(func)(*args, **kwargs)
           ^^^^^^^^^^^^^^^^^^^^^^^^^^^^^^^^^^^^^^^^^^^^^^
  File "D:\ASRP-main\asrp\blueprints\report\report_views.py", line 40, in report_statistics
    return render_template(
           ^^^^^^^^^^^^^^^^
  File "C:\Users\admin\AppData\Local\Programs\Python\Python311\Lib\site-packages\flask\templating.py", line 147, in render_template
    return _render(app, template, context)
           ^^^^^^^^^^^^^^^^^^^^^^^^^^^^^^^
  File "C:\Users\admin\AppData\Local\Programs\Python\Python311\Lib\site-packages\flask\templating.py", line 130, in _render
    rv = template.render(context)
         ^^^^^^^^^^^^^^^^^^^^^^^^
  File "C:\Users\admin\AppData\Local\Programs\Python\Python311\Lib\site-packages\jinja2\environment.py", line 1304, in render
    self.environment.handle_exception()
  File "C:\Users\admin\AppData\Local\Programs\Python\Python311\Lib\site-packages\jinja2\environment.py", line 939, in handle_exception
    raise rewrite_traceback_stack(source=source)
  File "D:\ASRP-main\asrp\templates\report\statistics.html", line 1, in top-level template code
    {% extends "base.html" %}
  File "D:\ASRP-main\asrp\templates\base.html", line 83, in top-level template code
    {% block content %}{% endblock %}
    ^^^^^^^^^^^^^^^^^^^^^^^^^
  File "D:\ASRP-main\asrp\templates\report\statistics.html", line 92, in block 'content'
    <div class="column module">{{ report.area.name }}</div>
    ^^^^^^^^^^^^^^^^^^^^^^^^^
  File "C:\Users\admin\AppData\Local\Programs\Python\Python311\Lib\site-packages\jinja2\environment.py", line 487, in getattr
    return getattr(obj, attribute)
           ^^^^^^^^^^^^^^^^^^^^^^^
jinja2.exceptions.UndefinedError: 'asrp.models.Report object' has no attribute 'area'
[2025-05-11 00:04:20,010] ERROR in app: Exception on /report/my_reports [GET]
Traceback (most recent call last):
  File "C:\Users\admin\AppData\Local\Programs\Python\Python311\Lib\site-packages\flask\app.py", line 2529, in wsgi_app
    response = self.full_dispatch_request()
               ^^^^^^^^^^^^^^^^^^^^^^^^^^^^
  File "C:\Users\admin\AppData\Local\Programs\Python\Python311\Lib\site-packages\flask\app.py", line 1825, in full_dispatch_request
    rv = self.handle_user_exception(e)
         ^^^^^^^^^^^^^^^^^^^^^^^^^^^^^
  File "C:\Users\admin\AppData\Local\Programs\Python\Python311\Lib\site-packages\flask\app.py", line 1823, in full_dispatch_request
    rv = self.dispatch_request()
         ^^^^^^^^^^^^^^^^^^^^^^^
  File "C:\Users\admin\AppData\Local\Programs\Python\Python311\Lib\site-packages\flask\app.py", line 1799, in dispatch_request
    return self.ensure_sync(self.view_functions[rule.endpoint])(**view_args)
           ^^^^^^^^^^^^^^^^^^^^^^^^^^^^^^^^^^^^^^^^^^^^^^^^^^^^^^^^^^^^^^^^^
  File "D:\ASRP-main\asrp\blueprints\report\__init__.py", line 26, in my_reports
    crime_reports = CrimeReport.query.all()
                    ^^^^^^^^^^^
NameError: name 'CrimeReport' is not defined
[2025-05-11 00:14:06,232] ERROR in app: Exception on /report/statistics [GET]
Traceback (most recent call last):
  File "C:\Users\admin\AppData\Local\Programs\Python\Python311\Lib\site-packages\flask\app.py", line 2529, in wsgi_app
    response = self.full_dispatch_request()
               ^^^^^^^^^^^^^^^^^^^^^^^^^^^^
  File "C:\Users\admin\AppData\Local\Programs\Python\Python311\Lib\site-packages\flask\app.py", line 1825, in full_dispatch_request
    rv = self.handle_user_exception(e)
         ^^^^^^^^^^^^^^^^^^^^^^^^^^^^^
  File "C:\Users\admin\AppData\Local\Programs\Python\Python311\Lib\site-packages\flask\app.py", line 1823, in full_dispatch_request
    rv = self.dispatch_request()
         ^^^^^^^^^^^^^^^^^^^^^^^
  File "C:\Users\admin\AppData\Local\Programs\Python\Python311\Lib\site-packages\flask\app.py", line 1799, in dispatch_request
    return self.ensure_sync(self.view_functions[rule.endpoint])(**view_args)
           ^^^^^^^^^^^^^^^^^^^^^^^^^^^^^^^^^^^^^^^^^^^^^^^^^^^^^^^^^^^^^^^^^
  File "C:\Users\admin\AppData\Local\Programs\Python\Python311\Lib\site-packages\flask_login\utils.py", line 290, in decorated_view
    return current_app.ensure_sync(func)(*args, **kwargs)
           ^^^^^^^^^^^^^^^^^^^^^^^^^^^^^^^^^^^^^^^^^^^^^^
  File "D:\ASRP-main\asrp\blueprints\report\report_views.py", line 40, in report_statistics
    return render_template(
           ^^^^^^^^^^^^^^^^
  File "C:\Users\admin\AppData\Local\Programs\Python\Python311\Lib\site-packages\flask\templating.py", line 147, in render_template
    return _render(app, template, context)
           ^^^^^^^^^^^^^^^^^^^^^^^^^^^^^^^
  File "C:\Users\admin\AppData\Local\Programs\Python\Python311\Lib\site-packages\flask\templating.py", line 130, in _render
    rv = template.render(context)
         ^^^^^^^^^^^^^^^^^^^^^^^^
  File "C:\Users\admin\AppData\Local\Programs\Python\Python311\Lib\site-packages\jinja2\environment.py", line 1304, in render
    self.environment.handle_exception()
  File "C:\Users\admin\AppData\Local\Programs\Python\Python311\Lib\site-packages\jinja2\environment.py", line 939, in handle_exception
    raise rewrite_traceback_stack(source=source)
  File "D:\ASRP-main\asrp\templates\report\statistics.html", line 1, in top-level template code
    {% extends "base.html" %}
  File "D:\ASRP-main\asrp\templates\base.html", line 83, in top-level template code
    {% block content %}{% endblock %}
    ^^^^^^^^^^^^^^^^^^^^^^^^^
  File "D:\ASRP-main\asrp\templates\report\statistics.html", line 92, in block 'content'
    <div class="column module">{{ report.area.name }}</div>
    ^^^^^^^^^^^^^^^^^^^^^^^^^
  File "C:\Users\admin\AppData\Local\Programs\Python\Python311\Lib\site-packages\jinja2\environment.py", line 487, in getattr
    return getattr(obj, attribute)
           ^^^^^^^^^^^^^^^^^^^^^^^
jinja2.exceptions.UndefinedError: 'asrp.models.Report object' has no attribute 'area'
[2025-05-11 00:14:08,589] ERROR in app: Exception on /report/my_reports [GET]
Traceback (most recent call last):
  File "C:\Users\admin\AppData\Local\Programs\Python\Python311\Lib\site-packages\flask\app.py", line 2529, in wsgi_app
    response = self.full_dispatch_request()
               ^^^^^^^^^^^^^^^^^^^^^^^^^^^^
  File "C:\Users\admin\AppData\Local\Programs\Python\Python311\Lib\site-packages\flask\app.py", line 1825, in full_dispatch_request
    rv = self.handle_user_exception(e)
         ^^^^^^^^^^^^^^^^^^^^^^^^^^^^^
  File "C:\Users\admin\AppData\Local\Programs\Python\Python311\Lib\site-packages\flask\app.py", line 1823, in full_dispatch_request
    rv = self.dispatch_request()
         ^^^^^^^^^^^^^^^^^^^^^^^
  File "C:\Users\admin\AppData\Local\Programs\Python\Python311\Lib\site-packages\flask\app.py", line 1799, in dispatch_request
    return self.ensure_sync(self.view_functions[rule.endpoint])(**view_args)
           ^^^^^^^^^^^^^^^^^^^^^^^^^^^^^^^^^^^^^^^^^^^^^^^^^^^^^^^^^^^^^^^^^
  File "D:\ASRP-main\asrp\blueprints\report\__init__.py", line 26, in my_reports
    crime_reports = CrimeReport.query.all()
                    ^^^^^^^^^^^
NameError: name 'CrimeReport' is not defined
[2025-05-11 00:20:57,531] ERROR in app: Exception on /report/statistics [GET]
Traceback (most recent call last):
  File "C:\Users\admin\AppData\Local\Programs\Python\Python311\Lib\site-packages\flask\app.py", line 2529, in wsgi_app
    response = self.full_dispatch_request()
               ^^^^^^^^^^^^^^^^^^^^^^^^^^^^
  File "C:\Users\admin\AppData\Local\Programs\Python\Python311\Lib\site-packages\flask\app.py", line 1825, in full_dispatch_request
    rv = self.handle_user_exception(e)
         ^^^^^^^^^^^^^^^^^^^^^^^^^^^^^
  File "C:\Users\admin\AppData\Local\Programs\Python\Python311\Lib\site-packages\flask\app.py", line 1823, in full_dispatch_request
    rv = self.dispatch_request()
         ^^^^^^^^^^^^^^^^^^^^^^^
  File "C:\Users\admin\AppData\Local\Programs\Python\Python311\Lib\site-packages\flask\app.py", line 1799, in dispatch_request
    return self.ensure_sync(self.view_functions[rule.endpoint])(**view_args)
           ^^^^^^^^^^^^^^^^^^^^^^^^^^^^^^^^^^^^^^^^^^^^^^^^^^^^^^^^^^^^^^^^^
  File "C:\Users\admin\AppData\Local\Programs\Python\Python311\Lib\site-packages\flask_login\utils.py", line 290, in decorated_view
    return current_app.ensure_sync(func)(*args, **kwargs)
           ^^^^^^^^^^^^^^^^^^^^^^^^^^^^^^^^^^^^^^^^^^^^^^
  File "D:\ASRP-main\asrp\blueprints\report\report_views.py", line 40, in report_statistics
    return render_template(
           ^^^^^^^^^^^^^^^^
  File "C:\Users\admin\AppData\Local\Programs\Python\Python311\Lib\site-packages\flask\templating.py", line 147, in render_template
    return _render(app, template, context)
           ^^^^^^^^^^^^^^^^^^^^^^^^^^^^^^^
  File "C:\Users\admin\AppData\Local\Programs\Python\Python311\Lib\site-packages\flask\templating.py", line 130, in _render
    rv = template.render(context)
         ^^^^^^^^^^^^^^^^^^^^^^^^
  File "C:\Users\admin\AppData\Local\Programs\Python\Python311\Lib\site-packages\jinja2\environment.py", line 1304, in render
    self.environment.handle_exception()
  File "C:\Users\admin\AppData\Local\Programs\Python\Python311\Lib\site-packages\jinja2\environment.py", line 939, in handle_exception
    raise rewrite_traceback_stack(source=source)
  File "D:\ASRP-main\asrp\templates\report\statistics.html", line 1, in top-level template code
    {% extends "base.html" %}
  File "D:\ASRP-main\asrp\templates\base.html", line 83, in top-level template code
    {% block content %}{% endblock %}
    ^^^^^^^^^^^^^^^^^^^^^^^^^
  File "D:\ASRP-main\asrp\templates\report\statistics.html", line 92, in block 'content'
    <div class="column module">{{ report.area.name }}</div>
    ^^^^^^^^^^^^^^^^^^^^^^^^^
  File "C:\Users\admin\AppData\Local\Programs\Python\Python311\Lib\site-packages\jinja2\environment.py", line 487, in getattr
    return getattr(obj, attribute)
           ^^^^^^^^^^^^^^^^^^^^^^^
jinja2.exceptions.UndefinedError: 'asrp.models.Report object' has no attribute 'area'
[2025-05-11 00:20:59,812] ERROR in app: Exception on /report/my_reports [GET]
Traceback (most recent call last):
  File "C:\Users\admin\AppData\Local\Programs\Python\Python311\Lib\site-packages\flask\app.py", line 2529, in wsgi_app
    response = self.full_dispatch_request()
               ^^^^^^^^^^^^^^^^^^^^^^^^^^^^
  File "C:\Users\admin\AppData\Local\Programs\Python\Python311\Lib\site-packages\flask\app.py", line 1825, in full_dispatch_request
    rv = self.handle_user_exception(e)
         ^^^^^^^^^^^^^^^^^^^^^^^^^^^^^
  File "C:\Users\admin\AppData\Local\Programs\Python\Python311\Lib\site-packages\flask\app.py", line 1823, in full_dispatch_request
    rv = self.dispatch_request()
         ^^^^^^^^^^^^^^^^^^^^^^^
  File "C:\Users\admin\AppData\Local\Programs\Python\Python311\Lib\site-packages\flask\app.py", line 1799, in dispatch_request
    return self.ensure_sync(self.view_functions[rule.endpoint])(**view_args)
           ^^^^^^^^^^^^^^^^^^^^^^^^^^^^^^^^^^^^^^^^^^^^^^^^^^^^^^^^^^^^^^^^^
  File "D:\ASRP-main\asrp\blueprints\report\__init__.py", line 28, in my_reports
    group_reports = CriminalGroupReport.query.all()
                    ^^^^^^^^^^^^^^^^^^^
NameError: name 'CriminalGroupReport' is not defined
